Workbook

Sheet Look Up Mobile
A1: Ladies Ring | E1: Discount
A2: Sn | B2: 217 | E2: 37.5 | F2: Cert Check
E3: =IF(G5>30,"G",IF(AND(G5>25,G5<30),"A",IF(AND(G5>20,G5<25),"B","C"))) -> B | F3: {=XLOOKUP(A1&B2, 'Certificate Data'!A:A, 'Certificate Data'!P:P)} -> SGLJNPJ342336E
A4: Net Weight | B4: {=VLOOKUP($B$2,INDIRECT("'"&A1&"'!$A$2:$S$999"), 2, 0)} -> 4.14 | C4: {=VLOOKUP($B$2,INDIRECT("'"&A1&"'!$A$2:$S$999"), 3, 0)} -> 1.035 | D4: {=VLOOKUP($B$2,INDIRECT("'"&A1&"'!$A$2:$S$999"), 4, 0)} -> 5.175 | E4: {=VLOOKUP($B$2,INDIRECT("'"&A1&"'!$A$2:$S$999"), 17, 0)} -> 92373.75 | F4: =IFERROR(E4/D4,0) -> 17850 | G4: =(((D4*0.6)/11.664)*Prices!A4)+D5*38000+D6*51900+D7*60900+D8*140000+D9*2000+D10*8000+D11*1200 -> 105855.56
A5: Dmd < 0.06 | D5: {=VLOOKUP($B$2,INDIRECT("'"&A1&"'!$A$2:$S$999"), 5, 0)} -> 0.6 | E5: {=VLOOKUP($B$2,INDIRECT("'"&A1&"'!$A$2:$S$999"), 12, 0)} -> 66000 | F5: =IFERROR(E5/D5,0) -> 110000 | G5: =((E17-G4)/E17)*100 -> 20.780882
A6: Dmd < 0.12 | D6: {=VLOOKUP($B$2,INDIRECT("'"&A1&"'!$A$2:$S$999"), 6, 0)} | E6: {=VLOOKUP($B$2,INDIRECT("'"&A1&"'!$A$2:$S$999"), 13, 0)} -> 0 | F6: =IFERROR(E6/D6,0) -> 0
A7: Dmd < 0.17 | D7: {=VLOOKUP($B$2,INDIRECT("'"&A1&"'!$A$2:$S$999"), 7, 0)} | E7: {=VLOOKUP($B$2,INDIRECT("'"&A1&"'!$A$2:$S$999"), 14, 0)} -> 0 | F7: =IFERROR(E7/D7,0) -> 0
A8: Dmd Big | D8: {=VLOOKUP($B$2,INDIRECT("'"&A1&"'!$A$2:$S$999"), 8, 0)} | E8: {=VLOOKUP($B$2,INDIRECT("'"&A1&"'!$A$2:$S$999"), 15, 0)} -> 0 | F8: =IFERROR(E8/D8,0) -> 0
A9: Ruby | D9: {=VLOOKUP($B$2,INDIRECT("'"&A1&"'!$A$2:$S$999"), 9, 0)} | E9: {=IF(D9<>0,VLOOKUP($B$2,INDIRECT("'"&A1&"'!$A$2:$S$999"),16,0),0)} -> 0 | F9: =IFERROR(E9/D9,0) -> 0
A10: Emreld | D10: {=VLOOKUP($B$2,INDIRECT("'"&A1&"'!$A$2:$S$999"), 10, 0)} | E10: {=IF(D10<>0,VLOOKUP($B$2,INDIRECT("'"&A1&"'!$A$2:$S$999"),16,0),0)} -> 0 | F10: =IFERROR(E10/D10,0) -> 0
A11: Muga | D11: {=VLOOKUP($B$2,INDIRECT("'"&A1&"'!$A$2:$S$999"), 11, 0)} | E11: {=IF(D11<>0,VLOOKUP($B$2,INDIRECT("'"&A1&"'!$A$2:$S$999"),16,0),0)} -> 0 | F11: =IFERROR(E11/D11,0) -> 0
D12: Gold Total | E12: {=VLOOKUP($B$2,INDIRECT("'"&A1&"'!$A$2:$S$999"), 17, 0)} -> 92373.75
D13: Diamond Total | E13: {=VLOOKUP($B$2,INDIRECT("'"&A1&"'!$A$2:$S$999"), 18, 0)} -> 66000
D14: Stone Total | E14: {=VLOOKUP($B$2,INDIRECT("'"&A1&"'!$A$2:$S$999"), 16, 0)} -> 0
D15: Total | E15: =E14+E12+E13 -> 158373.75
D16: Discount | E16: =E13*E2% -> 24750
D17: Net Total | E17: =E15-E16 -> 133623.75
D18: 2% Luxury Tax | E18: =E12*0.02 -> 1847.475
D19: Grand Total | E19: =E15-E16+E18 -> 135471.23

Sheet Bill Maker 1
C1: Discount | D1: 42 | E1: Gold Rate | F1: 296800 | G1: 1100 | K1: 14k | L1: =L12 -> 17850
A2: SN | B2: Description | C2: Net Wt | D2: Wastage | E2: Total Wt | F2: Rate | G2: Labour | H2: Taxable Amount | I2: Amount | L2: Rate
A3: AJ1 | B3: DJ Price | C3: {=VLOOKUP($A$3,INDIRECT("'"&B3&"'!$A$2:$S$999"), 2, 0)} -> 1.278 | D3: {=VLOOKUP($A$3,INDIRECT("'"&B3&"'!$A$2:$S$999"), 3, 0)} -> 0.3195 | E3: {=VLOOKUP($A$3,INDIRECT("'"&B3&"'!$A$2:$S$999"), 4, 0)} -> 1.5975 | F3: =ROUNDDOWN((F1/11.664)*0.6,0) -> 15267 | G3: =L4*E3 -> 1757.25 | H3: =(F3*E3)+G3 -> 26146.283 | K3: Gold | L3: =ROUNDDOWN((F1/11.664)*0.6,0) -> 15267
B4: Dmd < 0.06 | E4: {=VLOOKUP($A$3,INDIRECT("'"&B3&"'!$A$2:$S$999"), 5, 0)} -> 0.26 | F4: =P5 -> 73094.132 | I4: =F4*E4 -> 19004.474 | K4: Labour Rate | L4: 1100 | M4: =L12-L3 -> 2583 | P4: Rate | R4: =COUNTIF(E4:E7, ">0") -> 1
B5: Dmd < 0.12 | E5: {=VLOOKUP($A$3,INDIRECT("'"&B3&"'!$A$2:$S$999"), 6, 0)} | F5: =P6 -> 0 | I5: =F5*E5 -> 0 | K5: Dmd < 0.06 | L5: =IFERROR(M5/E4,0) -> 110000 | M5: {=VLOOKUP($A$3,INDIRECT("'"&B3&"'!$A$2:$S$999"), 12, 0)} -> 28600 | N5: =L5-(L5*$D$1%) -> 63800 | O5: Dmd < 0.06 | P5: =IFERROR(Q5/E4,0) -> 73094.132 | Q5: =IF(E4<>0,(N5*E4)+R5,0) -> 19004.474 | R5: =$R$15/$R$4 -> 2416.4743
B6: Dmd < 0.17 | E6: {=VLOOKUP($A$3,INDIRECT("'"&B3&"'!$A$2:$S$999"), 7, 0)} | F6: =P7 -> 0 | I6: =F6*E6 -> 0 | K6: Dmd < 0.12 | L6: =IFERROR(M6/E5,0) -> 0 | M6: {=VLOOKUP($A$3,INDIRECT("'"&B3&"'!$A$2:$S$999"), 13, 0)} -> 0 | N6: =L6-(L6*$D$1%) -> 0 | O6: Dmd < 0.12 | P6: =IFERROR(Q6/E5,0) -> 0 | Q6: =IF(E5<>0,(N6*E5)+R6,0) -> 0 | R6: =$R$15/$R$4 -> 2416.4743
B7: Dmd Big | E7: {=VLOOKUP($A$3,INDIRECT("'"&B3&"'!$A$2:$S$999"), 8, 0)} | F7: =P8 -> 0 | I7: =F7*E7 -> 0 | K7: Dmd < 0.17 | L7: =IFERROR(M7/E6,0) -> 0 | M7: {=VLOOKUP($A$3,INDIRECT("'"&B3&"'!$A$2:$S$999"), 14, 0)} -> 0 | N7: =L7-(L7*$D$1%) -> 0 | O7: Dmd < 0.17 | P7: =IFERROR(Q7/E6,0) -> 0 | Q7: =IF(E6<>0,(N7*E6)+R7,0) -> 0 | R7: =$R$15/$R$4 -> 2416.4743
B8: Ruby | E8: {=VLOOKUP($A$3,INDIRECT("'"&B3&"'!$A$2:$S$999"), 9, 0)} | F8: =IFERROR(I8/E8,0) -> 0 | I8: {=IF(E8<>0,VLOOKUP($A$3,INDIRECT("'"&B3&"'!$A$2:$S$999"),16,0),0)} -> 0 | K8: Dmd Big | L8: =IFERROR(M8/E7,0) -> 0 | M8: {=VLOOKUP($A$3,INDIRECT("'"&B3&"'!$A$2:$S$999"), 15, 0)} -> 0 | N8: =L8-(L8*$D$1%) -> 0 | O8: Dmd Big | P8: =IFERROR(Q8/E7,0) -> 0 | Q8: =IF(E7<>0,(N8*E7)+R8,0) -> 0 | R8: =$R$15/$R$4 -> 2416.4743
B9: Emreld | E9: {=VLOOKUP($A$3,INDIRECT("'"&B3&"'!$A$2:$S$999"), 10, 0)} | F9: =IFERROR(I9/E9,0) -> 0 | I9: {=IF(E9<>0,VLOOKUP($A$3,INDIRECT("'"&B3&"'!$A$2:$S$999"),16,0),0)} -> 0 | K9: Ruby | L9: =IFERROR(M9/E8,0) -> 0 | M9: {=IF(I8<>0,VLOOKUP($A$3,INDIRECT("'"&B3&"'!$A$2:$S$999"),16,0),0)} -> 0 | O9: Ruby | P9: =IFERROR(Q9/E8,0) -> 0 | Q9: {=IF(I8<>0,VLOOKUP($A$3,INDIRECT("'"&B3&"'!$A$2:$S$999"),16,0),0)} -> 0
B10: Muga | E10: {=VLOOKUP($A$3,INDIRECT("'"&B3&"'!$A$2:$S$999"), 11, 0)} | F10: =IFERROR(I10/E10,0) -> 0 | I10: {=IF(E10<>0,VLOOKUP($A$3,INDIRECT("'"&B3&"'!$A$2:$S$999"),16,0),0)} -> 0 | K10: Emreld | L10: =IFERROR(M10/E9,0) -> 0 | M10: {=IF(I9<>0,VLOOKUP($A$3,INDIRECT("'"&B3&"'!$A$2:$S$999"),16,0),0)} -> 0 | O10: Emreld | P10: =IFERROR(Q10/E9,0) -> 0 | Q10: {=IF(I9<>0,VLOOKUP($A$3,INDIRECT("'"&B3&"'!$A$2:$S$999"),16,0),0)} -> 0
G11: Discount | I11: 288 | K11: Muga | L11: =IFERROR(M11/E10,0) -> 0 | M11: {=IF(I10<>0,VLOOKUP($A$3,INDIRECT("'"&B3&"'!$A$2:$S$999"),16,0),0)} -> 0 | O11: Muga | P11: =IFERROR(Q11/E10,0) -> 0 | Q11: {=IF(I10<>0,VLOOKUP($A$3,INDIRECT("'"&B3&"'!$A$2:$S$999"),16,0),0)} -> 0
E12: Amount Before TAX | H12: =H3 -> 26146.283 | I12: =I4-I11+I10+I9+I7+I8+I6+I5 -> 18716.474 | K12: Gold | L12: =M12/E3 -> 17850 | M12: {=VLOOKUP($A$3,INDIRECT("'"&$B$3&"'!$A$2:$S$999"), 17, 0)} -> 28515.375 | O12: Gold | P12: =ROUNDDOWN((F1/11.664)*0.6,0) -> 15267 | Q12: =E3*P12 -> 24389.033
E13: 2% TAX | H13: =H12*0.02 -> 522.92565 | K13: Tax | M13: =M12*0.02 -> 570.3075 | O13: Labour | P13: 1100 | Q13: =E3*P13 -> 1757.25
E14: Grand Total | H14: =H12+I12+H13 -> 45385.683 | K14: Diamond | L14: =M14/(E4+E5+E6+E7) -> 110000 | M14: {=VLOOKUP($A$3,INDIRECT("'"&$B$3&"'!$A$2:$S$999"), 18, 0)} -> 28600 | O14: Tax | Q14: =(Q12+Q13)*0.02 -> 522.92565
K15: net | M15: =M14+M13+M12+M11+M10+M9 -> 57685.683 | O15: Diamond | Q15: =Q18-Q9-Q10-Q11-Q12-Q13-Q14 -> 19004.474 | R15: =Q15-M17 -> 2416.4743
K16: Discount | M16: =M14*D1% -> 12012 | O16: net
K17: Diamond Aft Disc | M17: =M14-M16 -> 16588 | O17: Discount
K18: Grand Total | M18: =M9+M10+M11+M12+M13+M14-M16 -> 45673.683 | O18: Grand Total | Q18: =M18 -> 45673.683

Sheet Bill Maker
F1: Gold Rate | G1: 238000 | H1: 14k Rate | I1: =IFERROR(H3/E3,0) -> 17850 | J1: =I1-F3 -> 5608
A2: SN | B2: Description | C2: Net Wt | D2: Wastage | E2: Total Wt | F2: Rate | G2: Labour | H2: Taxable Amount | I2: Amount | L2: Rate
A3: 337 | B3: Ladies Ring | C3: {=VLOOKUP($A$3,INDIRECT("'"&B3&"'!$A$2:$S$999"), 2, 0)} -> 3.442 | D3: {=VLOOKUP($A$3,INDIRECT("'"&B3&"'!$A$2:$S$999"), 3, 0)} -> 0.8605 | E3: {=VLOOKUP($A$3,INDIRECT("'"&B3&"'!$A$2:$S$999"), 4, 0)} -> 4.3025 | F3: =ROUNDDOWN((G1/11.664)*0.6,0) -> 12242 | G3: =J1*E3 -> 24128.42 | H3: {=VLOOKUP($A$3,INDIRECT("'"&B3&"'!$A$2:$S$999"), 17, 0)} -> 76799.625 | K3: Gold | L3: =ROUNDDOWN((G1/11.664)*0.6,0) -> 12242
B4: Dmd < 0.06 | E4: {=VLOOKUP($A$3,INDIRECT("'"&B3&"'!$A$2:$S$999"), 5, 0)} -> 0.54 | F4: =L4-(L4*E11%) -> 68200 | I4: =F4*E4 -> 36828 | K4: Dmd < 0.06 | L4: =IFERROR(M4/E4,0) -> 110000 | M4: {=VLOOKUP($A$3,INDIRECT("'"&B3&"'!$A$2:$S$999"), 12, 0)} -> 59400
B5: Dmd < 0.12 | E5: {=VLOOKUP($A$3,INDIRECT("'"&B3&"'!$A$2:$S$999"), 6, 0)} | F5: =IFERROR(I5/E5,0) -> 0 | I5: {=VLOOKUP($A$3,INDIRECT("'"&B3&"'!$A$2:$S$999"), 13, 0)} -> 0 | K5: Dmd < 0.12 | L5: =IFERROR(M5/E5,0) -> 0 | M5: {=VLOOKUP($A$3,INDIRECT("'"&B3&"'!$A$2:$S$999"), 13, 0)} -> 0
B6: Dmd < 0.17 | E6: {=VLOOKUP($A$3,INDIRECT("'"&B3&"'!$A$2:$S$999"), 7, 0)} | F6: =IFERROR(I6/E6,0) -> 0 | I6: {=VLOOKUP($A$3,INDIRECT("'"&B3&"'!$A$2:$S$999"), 14, 0)} -> 0 | K6: Dmd < 0.17 | L6: =IFERROR(M6/E6,0) -> 0 | M6: {=VLOOKUP($A$3,INDIRECT("'"&B3&"'!$A$2:$S$999"), 14, 0)} -> 0
B7: Dmd Big | E7: {=VLOOKUP($A$3,INDIRECT("'"&B3&"'!$A$2:$S$999"), 8, 0)} | F7: =IFERROR(I7/E7,0) -> 0 | I7: {=VLOOKUP($A$3,INDIRECT("'"&B3&"'!$A$2:$S$999"), 15, 0)} -> 0 | K7: Dmd Big | L7: =IFERROR(M7/E7,0) -> 0 | M7: {=VLOOKUP($A$3,INDIRECT("'"&B3&"'!$A$2:$S$999"), 15, 0)} -> 0
B8: Ruby | E8: {=VLOOKUP($A$3,INDIRECT("'"&B3&"'!$A$2:$S$999"), 9, 0)} | F8: =IFERROR(I8/E8,0) -> 0 | I8: {=IF(E8<>0,VLOOKUP($A$3,INDIRECT("'"&B3&"'!$A$2:$S$999"),16,0),0)} -> 0 | K8: Ruby | L8: =IFERROR(M8/E8,0) -> 0 | M8: {=IF(I8<>0,VLOOKUP($A$3,INDIRECT("'"&B3&"'!$A$2:$S$999"),16,0),0)} -> 0
B9: Emreld | E9: {=VLOOKUP($A$3,INDIRECT("'"&B3&"'!$A$2:$S$999"), 10, 0)} | F9: =IFERROR(I9/E9,0) -> 0 | I9: {=IF(E9<>0,VLOOKUP($A$3,INDIRECT("'"&B3&"'!$A$2:$S$999"),16,0),0)} -> 0 | K9: Emreld | L9: =IFERROR(M9/E9,0) -> 0 | M9: {=IF(I9<>0,VLOOKUP($A$3,INDIRECT("'"&B3&"'!$A$2:$S$999"),16,0),0)} -> 0
B10: Muga | E10: {=VLOOKUP($A$3,INDIRECT("'"&B3&"'!$A$2:$S$999"), 11, 0)} | F10: =IFERROR(I10/E10,0) -> 0 | I10: {=IF(E10<>0,VLOOKUP($A$3,INDIRECT("'"&B3&"'!$A$2:$S$999"),16,0),0)} -> 0 | K10: Muga | L10: =IFERROR(M10/E10,0) -> 0 | M10: {=IF(I10<>0,VLOOKUP($A$3,INDIRECT("'"&B3&"'!$A$2:$S$999"),16,0),0)} -> 0
E11: 38 | F11: % | G11: Discount | I11: 696
E12: Amount Before TAX | H12: {=VLOOKUP($A$3,INDIRECT("'"&B3&"'!$A$2:$S$999"), 17, 0)} -> 76799.625 | I12: =SUM(I4:I10)-I11 -> 36132
E13: 2% TAX | H13: =H12*0.02 -> 1535.9925
E14: Grand Total | H14: =H12+I12+H13 -> 114467.62

Sheet Gold Prices
A1: Gold | C1: 18K | F1: Gold | H1: 14K | K1: Conversion
A2: Weight | B2: 27 | C2: 0.12 | D2: % | F2: Weight | G2: 3.021 | H2: 0.2 | K2: =B2 -> 27 | L2: lal | M2: = | N2: =B2*0.1164 -> 3.1428 | O2: gm
A3: Jarti | B3: =B2*(C2) -> 3.24 | C3: =IF(A1="Gold",IF(C1="24K",B15,IF(C1="22K",B16,IF(C1="18K",B17,B18))),C15) -> 245200 | F3: Jarti | G3: =G2*(H2) -> 0.6042 | H3: =IF(F1="Gold",IF(H1="24K",G15,IF(H1="22K",G16,IF(H1="18K",G17,G18))),H15) -> 15766.461 | K3: =B3 -> 3.24 | L3: lal | M3: = | N3: =B3*0.1164 -> 0.377136 | O3: gm
A4: Total Weight | B4: =B2+B3 -> 30.24 | F4: Total Weight | G4: =G2+G3 -> 3.6252 | K4: =B4 -> 30.24 | L4: lal | M4: = | N4: =B4*0.1164 -> 3.519936 | O4: gm
A5: Jyala/pc | B5: 1500 | F5: Jyala/pc
A6: Jyala % | F6: Jyala % | G6: 5
A7: Jyala/tola | F7: Jyala/gm
A8: Total Price | B8: =IF($A$1="Gold",B4*(C3/100),B4*(C15)) -> 74148.48 | F8: Total Price | G8: =IF($A$1="Gold",G4*(H3),G4*(H15)) -> 57156.574
A9: Jyala | B9: =IF(B6<>0,((B4*B6%)*(C3/100)),IF(B7<>0,B7*B4,B5)) -> 1500 | F9: Jyala | G9: =IF(G6<>0,((G4*G6%)*(H3)),IF(G7<>0,G7*G4,G5)) -> 2857.8287
A10: Stone | F10: Stone
A11: Tax | B11: =IF(A1="Gold",SUM(B8:B9)*0.02,0) -> 1512.9696 | F11: Tax | G11: =IF(F1="Gold",SUM(G8:G9)*0.02,0) -> 1200.2881
A12: Grand Total | B12: =SUM(B8:B11) -> 77161.45 | F12: Grand Total | G12: =SUM(G8:G11) -> 61214.691
B14: Gold | C14: Silver | G14: Gold | H14: Silver
A15: 24K | B15: 306500 | C15: 4080 | F15: 24K | G15: =B15/11.664 -> 26277.435 | H15: 4080
A16: 22K | B16: =ROUNDUP(B15*91.6%, -1) -> 280760 | F16: 22K | G16: =ROUNDUP(G15*91.6%, -1) -> 24080
A17: 18K | B17: =B15*0.8 -> 245200 | F17: 18K | G17: =G15*0.8 -> 21021.948
A18: 14k | B18: =B15*0.6 -> 183900 | F18: 14K | G18: =G15*0.6 -> 15766.461

Sheet Look Up
A1: Ring Lookup | F1: =TODAY() -> 46179 | Q1: Discount % | R1: 40
A2: Sn | B2: Net Weight | C2: Wstg + MC | D2: Gross Weight | E2: Dmd <0.06 | F2: Dmd < 0.12 | G2: Dmd <0.17 | H2: Dmd Big | I2: Ruby | J2: Emreld | K2: Muga | L2: Dmd Price | M2: Dmd Price | N2: Dmd Price | O2: Dmd Price | P2: Stn Price | Q2: Gold Price | R2: Ttl dmd Price | S2: Total Price | T2: Tax | W2: =(((D3*0.6)/11.664)*Prices!A4)+E3*38000+F3*51900+G3*60900+H3*140000+I3*1000+J3*3000+K3*300 -> 250769.14
A3: 232 | B3: =VLOOKUP($A$3,'Ladies Ring'!$A$2:$S$998, 2, 0) -> 9.382 | C3: =VLOOKUP($A$3,'Ladies Ring'!$A$2:$S$998, 3, 0) -> 2.3455 | D3: =VLOOKUP($A$3,'Ladies Ring'!$A$2:$S$998, 4, 0) -> 11.7275 | E3: =VLOOKUP($A$3,'Ladies Ring'!$A$2:$S$998, 5, 0) -> 1.59 | F3: =VLOOKUP($A$3,'Ladies Ring'!$A$2:$S$998, 6, 0) | G3: =VLOOKUP($A$3,'Ladies Ring'!$A$2:$S$998, 7, 0) | H3: =VLOOKUP($A$3,'Ladies Ring'!$A$2:$S$998, 8, 0) | I3: =VLOOKUP($A$3,'Ladies Ring'!$A$2:$S$998, 9, 0) | J3: =VLOOKUP($A$3,'Ladies Ring'!$A$2:$S$998, 10, 0) | K3: =VLOOKUP($A$3,'Ladies Ring'!$A$2:$S$998, 11, 0) -> 7.1 | L3: =VLOOKUP($A$3,'Ladies Ring'!$A$2:$S$998, 12, 0) -> 174900 | M3: =VLOOKUP($A$3,'Ladies Ring'!$A$2:$S$998, 13, 0) -> 0 | N3: =VLOOKUP($A$3,'Ladies Ring'!$A$2:$S$998, 14, 0) -> 0 | O3: =VLOOKUP($A$3,'Ladies Ring'!$A$2:$S$998, 15, 0) -> 0 | P3: =VLOOKUP($A$3,'Ladies Ring'!$A$2:$S$998, 16, 0) -> 12780 | Q3: =VLOOKUP($A$3,'Ladies Ring'!$A$2:$S$998, 17, 0) -> 209335.88 | R3: =VLOOKUP($A$3,'Ladies Ring'!$A$2:$S$998, 18, 0) -> 174900 | S3: =VLOOKUP($A$3,'Ladies Ring'!$A$2:$S$998, 19, 0) -> 397015.88 | T3: =Q3*0.02 -> 4186.7175 | W3: =((S4-W2)/S4)*100 -> 24.294417
L4: =IFERROR(L3/E3,0) -> 110000 | M4: =IFERROR(M3/F3,0) -> 0 | N4: =IFERROR(N3/G3,0) -> 0 | O4: =IFERROR(O3/H3,0) -> 0 | P4: =IFERROR(P3/(K3+J3+I3),0) -> 1800 | Q4: =IFERROR(Q3/D3,0) -> 17850 | R4: =R3-(R3*(R1/100)) -> 104940 | S4: =R4+Q3+P3+T3 -> 331242.59 | T4: =IF(W3>30,"G",IF(AND(W3>25,W3<30),"A",IF(AND(W3>20,W3<25),"B","C"))) -> B
R5: =R3-R4 -> 69960
A6: Gents Ring
A7: Sn | B7: Net Weight | C7: Wstg + MC | D7: Gross Weight | E7: Dmd <0.06 | F7: Dmd < 0.12 | G7: Dmd <0.17 | H7: Dmd Big | I7: Ruby | J7: Emreld | K7: Muga | L7: Dmd Price | M7: Dmd Price | N7: Dmd Price | O7: Dmd Price | P7: Stn Price | Q7: Gold Price | R7: Ttl dmd Price | S7: Total Price | T7: Tax | W7: =(((D8*0.6)/11.664)*Prices!A4)+E8*38000+F8*51900+G8*60900+H8*140000+I8*1000+J8*3000+K8*300 -> 131610.68
A8: 40 | B8: =VLOOKUP($A$8,'Gents Ring'!A2:S999, 2, 0) -> 3.98 | C8: =VLOOKUP($A$8,'Gents Ring'!A2:S999, 3, 0) -> 0.995 | D8: =VLOOKUP($A$8,'Gents Ring'!A2:S999, 4, 0) -> 4.975 | E8: =VLOOKUP($A$8,'Gents Ring'!A2:S999, 5, 0) | F8: =VLOOKUP($A$8,'Gents Ring'!A2:S999, 6, 0) | G8: =VLOOKUP($A$8,'Gents Ring'!A2:S999, 7, 0) -> 0.85 | H8: =VLOOKUP($A$8,'Gents Ring'!A2:S999, 8, 0) | I8: =VLOOKUP($A$8,'Gents Ring'!A2:S999, 9, 0) | J8: =VLOOKUP($A$8,'Gents Ring'!A2:S999, 10, 0) | K8: =VLOOKUP($A$8,'Gents Ring'!A2:S999, 11, 0) | L8: =VLOOKUP($A$8,'Gents Ring'!A2:S999, 12, 0) -> 0 | M8: =VLOOKUP($A$8,'Gents Ring'!A2:S999, 13, 0) -> 0 | N8: =VLOOKUP($A$8,'Gents Ring'!A2:S999, 14, 0) -> 165750 | O8: =VLOOKUP($A$8,'Gents Ring'!A2:S999, 15, 0) -> 0 | P8: =VLOOKUP($A$8,'Gents Ring'!A2:S999, 16, 0) -> 0 | Q8: =VLOOKUP($A$8,'Gents Ring'!A2:S999, 17, 0) -> 88803.75 | R8: =VLOOKUP($A$8,'Gents Ring'!A2:S999, 18, 0) -> 165750 | S8: =VLOOKUP($A$8,'Gents Ring'!A2:S999, 19, 0) -> 254553.75 | T8: =Q8*0.02 -> 1776.075 | W8: =((S9-W7)/S9)*100 -> 30.742093
L9: =IFERROR(L8/E8,0) -> 0 | M9: =IFERROR(M8/F8,0) -> 0 | N9: =IFERROR(N8/G8,0) -> 195000 | O9: =IFERROR(O8/H8,0) -> 0 | P9: =IFERROR(P8/(K8+J8+I8),0) -> 0 | Q9: =IFERROR(Q8/D8,0) -> 17850 | R9: =R8-(R8*(R1/100)) -> 99450 | S9: =R9+Q8+P8+T8 -> 190029.83 | T9: =IF(W8>30,"G",IF(AND(W8>25,W8<30),"A",IF(AND(W8>20,W8<25),"B","C"))) -> G
R10: =R8-R9 -> 66300
A11: Top Lookup
A12: Sn | B12: Net Weight | C12: Wstg + MC | D12: Gross weight | E12: Dmd <0.06 | F12: Dmd < 0.12 | G12: Dmd <0.17 | H12: Dmd Big | I12: Ruby | J12: Emreld | K12: Muga | L12: Dmd Price | M12: Dmd Price | N12: Dmd Price | O12: Dmd Price | P12: Stn Price | Q12: Gold Price | R12: Ttl dmd Price | S12: Total Price | T12: Tax | W12: =(((D13*0.6)/11.664)*Prices!A4)+E13*38000+F13*55000+G13*60900+H13*140000+I13*1000+J13*3000+K13*300 -> 200806.79
A13: 93 | B13: =VLOOKUP($A$13,Top!A2:S1000, 2, 0) -> 8.21 | C13: =VLOOKUP($A$13,Top!A2:S1000, 3, 0) -> 2.0525 | D13: =VLOOKUP($A$13,Top!A2:S1000, 4, 0) -> 10.2625 | E13: =VLOOKUP($A$13,Top!A2:S1000, 5, 0) -> 0.95 | F13: =VLOOKUP($A$13,Top!A2:S1000, 6, 0) | G13: =VLOOKUP($A$13,Top!A2:S1000, 7, 0) | H13: =VLOOKUP($A$13,Top!A2:S1000, 8, 0) | I13: =VLOOKUP($A$13,Top!A2:S1000, 9, 0) | J13: =VLOOKUP($A$13,Top!A2:S1000, 10, 0) | K13: =VLOOKUP($A$13,Top!A2:S1000, 11, 0) | L13: =VLOOKUP($A$13,Top!A2:S1000, 12, 0) -> 104500 | M13: =VLOOKUP($A$13,Top!A2:S1000, 13, 0) -> 0 | N13: =VLOOKUP($A$13,Top!A2:S1000, 14, 0) -> 0 | O13: =VLOOKUP($A$13,Top!A2:S1000, 15, 0) -> 0 | P13: =VLOOKUP($A$13,Top!A2:S1000, 16, 0) -> 0 | Q13: =VLOOKUP($A$13,Top!A2:S1000, 17, 0) -> 183185.62 | R13: =VLOOKUP($A$13,Top!A2:S1000, 18, 0) -> 104500 | S13: =VLOOKUP($A$13,Top!A2:S1000, 19, 0) -> 287685.62 | T13: =Q13*0.02 -> 3663.7125 | W13: =((S14-W12)/S14)*100 -> 19.532229
L14: =IFERROR(L13/E13,0) -> 110000 | M14: =IFERROR(M13/F13,0) -> 0 | N14: =IFERROR(N13/G13,0) -> 0 | O14: =IFERROR(O13/H13,0) -> 0 | P14: =IFERROR(P13/(K13+J13+I13),0) -> 0 | Q14: =IFERROR(Q13/D13,0) -> 17850 | R14: =R13-(R13*(R1/100)) -> 62700 | S14: =R14+Q13+P13+T13 -> 249549.34 | T14: =IF(W13>30,"G",IF(AND(W13>25,W13<30),"A",IF(AND(W13>20,W13<25),"B","C"))) -> C
R15: =R13-R14 -> 41800
A16: Pendent Lookup
A18: Sn | B18: Net Weight | C18: Wstg + MC | D18: Gross weight | E18: Dmd <0.06 | F18: Dmd < 0.12 | G18: Dmd <0.17 | H18: Dmd Big | I18: Ruby | J18: Emreld | K18: Muga | L18: Dmd Price | M18: Dmd Price | N18: Dmd Price | O18: Dmd Price | P18: Stn Price | Q18: Gold Price | R18: Ttl dmd Price | S18: Total Price | T18: Tax | W18: =(((D19*0.6)/11.664)*Prices!A4)+E19*38000+F19*51900+G19*60900+H19*140000+I19*1000+J19*3000+K19*300 -> #REF!
A19: 1 | B19: =VLOOKUP($A$19,#REF!, 2, 0) -> #REF! | C19: =VLOOKUP($A$19,#REF!, 3, 0) -> #REF! | D19: =VLOOKUP($A$19,#REF!, 4, 0) -> #REF! | E19: =VLOOKUP($A$19,#REF!, 5, 0) -> #REF! | F19: =VLOOKUP($A$19,#REF!, 6, 0) -> #REF! | G19: =VLOOKUP($A$19,#REF!, 7, 0) -> #REF! | H19: =VLOOKUP($A$19,#REF!, 8, 0) -> #REF! | I19: =VLOOKUP($A$19,#REF!, 9, 0) -> #REF! | J19: =VLOOKUP($A$19,#REF!, 10, 0) -> #REF! | K19: =VLOOKUP($A$19,#REF!, 11, 0) -> #REF! | L19: =VLOOKUP($A$19,#REF!, 12, 0) -> #REF! | M19: =VLOOKUP($A$19,#REF!, 13, 0) -> #REF! | N19: =VLOOKUP($A$19,#REF!, 14, 0) -> #REF! | O19: =VLOOKUP($A$19,#REF!, 15, 0) -> #REF! | P19: =VLOOKUP($A$19,#REF!, 16, 0) -> #REF! | Q19: =VLOOKUP($A$19,#REF!, 17, 0) -> #REF! | R19: =VLOOKUP($A$19,#REF!, 18, 0) -> #REF! | S19: =VLOOKUP($A$19,#REF!, 19, 0) -> #REF! | T19: =Q19*0.02 -> #REF! | W19: =((S20-W18)/S20)*100 -> #REF!
L20: =IFERROR(L19/E19,0) -> 0 | M20: =IFERROR(M19/F19,0) -> 0 | N20: =IFERROR(N19/G19,0) -> 0 | O20: =IFERROR(O19/H19,0) -> 0 | P20: =IFERROR(P19/(K19+J19+I19),0) -> 0 | Q20: =IFERROR(Q19/D19,0) -> 0 | R20: =R19-(R19*(R1/100)) -> #REF! | S20: =R20+Q19+P19+T19 -> #REF! | T20: =IF(W19>30,"G",IF(AND(W19>25,W19<30),"A",IF(AND(W19>20,W19<25),"B","C"))) -> #REF!
R21: =R19-R20 -> #REF!
A22: Locket Lookup
A23: Sn | B23: Net Weight | C23: Wstg + MC | D23: Gross Weight | E23: Dmd <0.06 | F23: Dmd < 0.12 | G23: Dmd <0.17 | H23: Dmd Big | I23: Ruby | J23: Emreld | K23: Muga | L23: Dmd Price | M23: Dmd Price | N23: Dmd Price | O23: Dmd Price | P23: Stn Price | Q23: Gold Price | R23: Ttl dmd Price | S23: Total Price | T23: Tax | W23: =(((D24*0.6)/11.664)*Prices!A4)+E24*38000+F24*51900+G24*60900+H24*140000+I24*1000+J24*3000+K24*300 -> 293844.07
A24: 33 | B24: =VLOOKUP($A$24,Locket!A2:S999, 2, 0) -> 11.73 | C24: =VLOOKUP($A$24,Locket!A2:S999, 3, 0) -> 2.9325 | D24: =VLOOKUP($A$24,Locket!A2:S999, 4, 0) -> 14.6625 | E24: =VLOOKUP($A$24,Locket!A2:S999, 5, 0) -> 1.54 | F24: =VLOOKUP($A$24,Locket!A2:S999, 6, 0) | G24: =VLOOKUP($A$24,Locket!A2:S999, 7, 0) | H24: =VLOOKUP($A$24,Locket!A2:S999, 8, 0) | I24: =VLOOKUP($A$24,Locket!A2:S999, 9, 0) | J24: =VLOOKUP($A$24,Locket!A2:S999, 10, 0) | K24: =VLOOKUP($A$24,Locket!A2:S999, 11, 0) | L24: =VLOOKUP($A$24,Locket!A2:S999, 12, 0) -> 169400 | M24: =VLOOKUP($A$24,Locket!A2:S999, 13, 0) -> 0 | N24: =VLOOKUP($A$24,Locket!A2:S999, 14, 0) -> 0 | O24: =VLOOKUP($A$24,Locket!A2:S999, 15, 0) -> 0 | P24: =VLOOKUP($A$24,Locket!A2:S999, 16, 0) -> 0 | Q24: =VLOOKUP($A$24,Locket!A2:S999, 17, 0) -> 261725.62 | R24: =VLOOKUP($A$24,Locket!A2:S999, 18, 0) -> 169400 | S24: =VLOOKUP($A$24,Locket!A2:S999, 19, 0) -> 431125.62 | T24: =Q24*0.02 -> 5234.5125 | W24: =((S25-W23)/S25)*100 -> 20.281073
L25: =IFERROR(L24/E24,0) -> 110000 | M25: =IFERROR(M24/F24,0) -> 0 | N25: =IFERROR(N24/G24,0) -> 0 | O25: =IFERROR(O24/H24,0) -> 0 | P25: =IFERROR(P24/(K24+J24+I24),0) -> 0 | Q25: =IFERROR(Q24/D24,0) -> 17850 | R25: =R24-(R24*(R1/100)) -> 101640 | S25: =R25+Q24+P24+T24 -> 368600.14 | T25: =IF(W24>30,"G",IF(AND(W24>25,W24<30),"A",IF(AND(W24>20,W24<25),"B","C"))) -> B
R26: =R24-R25 -> 67760
A27: Jagganath Lookup
A28: Sn | B28: Net Weight | C28: Wstg + MC | D28: Gross weight | E28: Dmd <0.06 | F28: Dmd < 0.12 | G28: Dmd <0.17 | H28: Dmd Big | I28: Ruby | J28: Emreld | K28: Muga | L28: Dmd Price | M28: Dmd Price | N28: Dmd Price | O28: Dmd Price | P28: Stn Price | Q28: Gold Price | R28: Ttl dmd Price | S28: Total Price | T28: Tax | W28: =(((D29*0.6)/11.664)*Prices!A4)+E29*38000+F29*51900+G29*60900+H29*140000+I29*1000+J29*3000+K29*300 -> 45155.679
A29: 21 | B29: =VLOOKUP($A$29,Jagganath!A2:S996, 2, 0) -> 1.55 | C29: =VLOOKUP($A$29,Jagganath!A2:S996, 3, 0) -> 0.3875 | D29: =VLOOKUP($A$29,Jagganath!A2:S996, 4, 0) -> 1.9375 | E29: =VLOOKUP($A$29,Jagganath!A2:S996, 5, 0) -> 0.37 | F29: =VLOOKUP($A$29,Jagganath!A2:S996, 6, 0) | G29: =VLOOKUP($A$29,Jagganath!A2:S996, 7, 0) | H29: =VLOOKUP($A$29,Jagganath!A2:S996, 8, 0) | I29: =VLOOKUP($A$29,Jagganath!A2:S996, 9, 0) | J29: =VLOOKUP($A$29,Jagganath!A2:S996, 10, 0) | K29: =VLOOKUP($A$29,Jagganath!A2:S996, 11, 0) | L29: =VLOOKUP($A$29,Jagganath!A2:S996, 12, 0) -> 40700 | M29: =VLOOKUP($A$29,Jagganath!A2:S996, 13, 0) -> 0 | N29: =VLOOKUP($A$29,Jagganath!A2:S996, 14, 0) -> 0 | O29: =VLOOKUP($A$29,Jagganath!A2:S996, 15, 0) -> 0 | P29: =VLOOKUP($A$29,Jagganath!A2:S996, 16, 0) -> 0 | Q29: =VLOOKUP($A$29,Jagganath!A2:S996, 17, 0) -> 34584.375 | R29: =VLOOKUP($A$29,Jagganath!A2:S996, 18, 0) -> 40700 | S29: =VLOOKUP($A$29,Jagganath!A2:S996, 19, 0) -> 75284.375 | T29: =Q29*0.02 -> 691.6875 | W29: =((S30-W28)/S30)*100 -> 24.357358
L30: =IFERROR(L29/E29,0) -> 110000 | M30: =IFERROR(M29/F29,0) -> 0 | N30: =IFERROR(N29/G29,0) -> 0 | O30: =IFERROR(O29/H29,0) -> 0 | P30: =IFERROR(P29/(K29+J29+I29),0) -> 0 | Q30: =IFERROR(Q29/D29,0) -> 17850 | R30: =R29-(R29*(R1/100)) -> 24420 | S30: =R30+Q29+P29+T29 -> 59696.062 | T30: =IF(W29>30,"G",IF(AND(W29>25,W29<30),"A",IF(AND(W29>20,W29<25),"B","C"))) -> B
R31: =R29-R30 -> 16280
A32: Jagganath Lookup
A33: Sn | B33: Net Weight | C33: Wstg + MC | D33: Gross weight | E33: Dmd <0.06 | F33: Dmd < 0.12 | G33: Dmd <0.17 | H33: Dmd Big | I33: Ruby | J33: Emreld | K33: Muga | L33: Dmd Price | M33: Dmd Price | N33: Dmd Price | O33: Dmd Price | P33: Stn Price | Q33: Gold Price | R33: Ttl dmd Price | S33: Total Price | T33: Tax | W33: =(((D34*0.6)/11.664)*Prices!A4)+E34*38000+F34*51900+G34*60900+H34*140000+I34*1000+J34*3000+K34*300 -> 51735.926
A34: 85720 | B34: =VLOOKUP($A$34,Prithivi!A2:S995, 2, 0) -> 1.878 | C34: =VLOOKUP($A$34,Prithivi!A2:S995, 3, 0) -> 0.4695 | D34: =VLOOKUP($A$34,Prithivi!A2:S995, 4, 0) -> 2.3475 | E34: =VLOOKUP($A$34,Prithivi!A2:S995, 5, 0) -> 0.37 | F34: =VLOOKUP($A$34,Prithivi!A2:S995, 6, 0) | G34: =VLOOKUP($A$34,Prithivi!A2:S995, 7, 0) | H34: =VLOOKUP($A$34,Prithivi!A2:S995, 8, 0) | I34: =VLOOKUP($A$34,Prithivi!A2:S995, 9, 0) | J34: =VLOOKUP($A$34,Prithivi!A2:S995, 10, 0) | K34: =VLOOKUP($A$34,Prithivi!A2:S995, 11, 0) | L34: =VLOOKUP($A$34,Prithivi!A2:S995, 12, 0) -> 40700 | M34: =VLOOKUP($A$34,Prithivi!A2:S995, 13, 0) -> 0 | N34: =VLOOKUP($A$34,Prithivi!A2:S995, 14, 0) -> 0 | O34: =VLOOKUP($A$34,Prithivi!A2:S995, 15, 0) -> 0 | P34: =VLOOKUP($A$34,Prithivi!A2:S995, 16, 0) -> 0 | Q34: =VLOOKUP($A$34,Prithivi!A2:S995, 17, 0) -> 41902.875 | R34: =VLOOKUP($A$34,Prithivi!A2:S995, 18, 0) -> 40700 | S34: =VLOOKUP($A$34,Prithivi!A2:S995, 19, 0) -> 82602.875 | T34: =Q34*0.02 -> 838.0575 | W34: =((S35-W33)/S35)*100 -> 22.967231
L35: =IFERROR(L34/E34,0) -> 110000 | M35: =IFERROR(M34/F34,0) -> 0 | N35: =IFERROR(N34/G34,0) -> 0 | O35: =IFERROR(O34/H34,0) -> 0 | P35: =IFERROR(P34/(K34+J34+I34),0) -> 0 | Q35: =IFERROR(Q34/D34,0) -> 17850 | R35: =R34-(R34*(R1/100)) -> 24420 | S35: =R35+Q34+P34+T34 -> 67160.932 | T35: =IF(W34>30,"G",IF(AND(W34>25,W34<30),"A",IF(AND(W34>20,W34<25),"B","C"))) -> B
R36: =R34-R35 -> 16280
A37: Necklace Lookup
A38: Sn | B38: Net Weight | C38: Wstg + MC | D38: Gross weight | E38: Dmd <0.06 | F38: Dmd < 0.12 | G38: Dmd <0.17 | H38: Dmd Big | I38: Ruby | J38: Emreld | K38: Muga | L38: Dmd Price | M38: Dmd Price | N38: Dmd Price | O38: Dmd Price | P38: Stn Price | Q38: Gold Price | R38: Ttl dmd Price | S38: Total Price | T38: Tax | W38: =(((D39*0.6)/11.664)*Prices!A4)+E39*38000+F39*51900+G39*60900+H39*140000+I39*1000+J39*3000+K39*300 -> 696704.9
A39: 1 | B39: =VLOOKUP($A$39,Necklace!A1:T999, 2, 0) -> 23.132 | C39: =VLOOKUP($A$39,Necklace!A1:T999, 3, 0) -> 5.783 | D39: =VLOOKUP($A$39,Necklace!A1:T999, 4, 0) -> 28.915 | E39: =VLOOKUP($A$39,Necklace!A1:T999, 5, 0) -> 6.1 | F39: =VLOOKUP($A$39,Necklace!A1:T999, 6, 0) | G39: =VLOOKUP($A$39,Necklace!A1:T999, 7, 0) | H39: =VLOOKUP($A$39,Necklace!A1:T999, 8, 0) | I39: =VLOOKUP($A$39,Necklace!A1:T999, 9, 0) | J39: =VLOOKUP($A$39,Necklace!A1:T999, 10, 0) | K39: =VLOOKUP($A$39,Necklace!A1:T999, 11, 0) -> 2.79 | L39: =VLOOKUP($A$39,Necklace!A1:T999, 12, 0) -> 671000 | M39: =VLOOKUP($A$39,Necklace!A1:T999, 13, 0) -> 0 | N39: =VLOOKUP($A$39,Necklace!A1:T999, 14, 0) -> 0 | O39: =VLOOKUP($A$39,Necklace!A1:T999, 15, 0) -> 0 | P39: =VLOOKUP($A$39,Necklace!A1:T999, 16, 0) -> 1813.5 | Q39: =VLOOKUP($A$39,Necklace!A1:T999, 17, 0) -> 516132.75 | R39: =VLOOKUP($A$39,Necklace!A1:T999, 18, 0) -> 671000 | S39: =VLOOKUP($A$39,Necklace!A1:T999, 19, 0) -> 1188946.2 | T39: =Q39*0.02 -> 10322.655 | W39: =((S40-W38)/S40)*100 -> 25.155422
L40: =IFERROR(L39/E39,0) -> 110000 | M40: =IFERROR(M39/F39,0) -> 0 | N40: =IFERROR(N39/G39,0) -> 0 | O40: =IFERROR(O39/H39,0) -> 0 | P40: =IFERROR(P39/(K39+J39+I39),0) -> 650 | Q40: =IFERROR(Q39/D39,0) -> 17850 | R40: =R39-(R39*(R1/100)) -> 402600 | S40: =R40+Q39+P39+T39 -> 930868.91 | T40: =IF(W34>30,"G",IF(AND(W34>25,W34<30),"A",IF(AND(W34>20,W34<25),"B","C"))) -> B
R41: =R39-R40 -> 268400
...

Sheet Ladies Ring
A1: Sn | B1: Net Weight | C1: Wstg + MC | D1: Gross Weight | E1: Dmd <0.06 | F1: Dmd < 0.12 | G1: Dmd <0.17 | H1: Dmd Big | I1: Ruby | J1: Emreld | K1: Muga | L1: Dmd Price | M1: Dmd Price | N1: Dmd Price | O1: Dmd Price | P1: Stn Price | Q1: Gold Price | R1: Ttl dmd Price | S1: Total Price | T1: Sn
A2: 1 | B2: 6.06 | C2: =B2*(25/100) -> 1.515 | D2: =C2+B2 -> 7.575 | E2: 0.54 | L2: =E2*Prices!B$2 -> 59400 | M2: =F2*Prices!C$2 -> 0 | N2: =G2*Prices!D$2 -> 0 | O2: =H2*Prices!E$2 -> 0 | P2: =I2*2000+J2*10000+K2*1800 -> 0 | Q2: =D2*Prices!A$2 -> 135213.75 | R2: =L2+M2+N2+O2 -> 59400 | S2: =R2+Q2+P2 -> 194613.75 | T2: 1 | U2: Available | V2: A
A3: 2 | B3: 2.986 | C3: =B3*(25/100) -> 0.7465 | D3: =C3+B3 -> 3.7325 | E3: 0.5 | L3: =E3*Prices!B$2 -> 55000 | M3: =F3*Prices!C$2 -> 0 | N3: =G3*Prices!D$2 -> 0 | O3: =H3*Prices!E$2 -> 0 | P3: =I3*2000+J3*10000+K3*1800 -> 0 | Q3: =D3*Prices!A$2 -> 66625.125 | R3: =L3+M3+N3+O3 -> 55000 | S3: =R3+Q3+P3 -> 121625.12 | T3: 2 | U3: Sold
A4: 3 | B4: 5.86 | C4: =B4*(25/100) -> 1.465 | D4: =C4+B4 -> 7.325 | E4: 1.19 | L4: =E4*Prices!B$2 -> 130900 | M4: =F4*Prices!C$2 -> 0 | N4: =G4*Prices!D$2 -> 0 | O4: =H4*Prices!E$2 -> 0 | P4: =I4*2000+J4*10000+K4*1800 -> 0 | Q4: =D4*Prices!A$2 -> 130751.25 | R4: =L4+M4+N4+O4 -> 130900 | S4: =R4+Q4+P4 -> 261651.25 | T4: 3 | U4: Sold
A5: 4 | B5: 1.79 | C5: =B5*(25/100) -> 0.4475 | D5: =C5+B5 -> 2.2375 | E5: 0.18 | L5: =E5*Prices!B$2 -> 19800 | M5: =F5*Prices!C$2 -> 0 | N5: =G5*Prices!D$2 -> 0 | O5: =H5*Prices!E$2 -> 0 | P5: =I5*2000+J5*10000+K5*1800 -> 0 | Q5: =D5*Prices!A$2 -> 39939.375 | R5: =L5+M5+N5+O5 -> 19800 | S5: =R5+Q5+P5 -> 59739.375 | T5: 4 | U5: Sold
A6: 5 | B6: 2.194 | C6: =B6*(25/100) -> 0.5485 | D6: =C6+B6 -> 2.7425 | E6: 0.35 | L6: =E6*Prices!B$2 -> 38500 | M6: =F6*Prices!C$2 -> 0 | N6: =G6*Prices!D$2 -> 0 | O6: =H6*Prices!E$2 -> 0 | P6: =I6*2000+J6*10000+K6*1800 -> 0 | Q6: =D6*Prices!A$2 -> 48953.625 | R6: =L6+M6+N6+O6 -> 38500 | S6: =R6+Q6+P6 -> 87453.625 | T6: 5 | U6: Sold
A7: 6 | B7: 1.95 | C7: =B7*(25/100) -> 0.4875 | D7: =C7+B7 -> 2.4375 | E7: 0.33 | L7: =E7*Prices!B$2 -> 36300 | M7: =F7*Prices!C$2 -> 0 | N7: =G7*Prices!D$2 -> 0 | O7: =H7*Prices!E$2 -> 0 | P7: =I7*2000+J7*10000+K7*1800 -> 0 | Q7: =D7*Prices!A$2 -> 43509.375 | R7: =L7+M7+N7+O7 -> 36300 | S7: =R7+Q7+P7 -> 79809.375 | T7: 6 | U7: Available | V7: A
A8: 7 | B8: 2.75 | C8: =B8*(25/100) -> 0.6875 | D8: =C8+B8 -> 3.4375 | E8: 0.75 | L8: =E8*Prices!B$2 -> 82500 | M8: =F8*Prices!C$2 -> 0 | N8: =G8*Prices!D$2 -> 0 | O8: =H8*Prices!E$2 -> 0 | P8: =I8*2000+J8*10000+K8*1800 -> 0 | Q8: =D8*Prices!A$2 -> 61359.375 | R8: =L8+M8+N8+O8 -> 82500 | S8: =R8+Q8+P8 -> 143859.38 | T8: 7 | U8: Sold
A9: 8 | B9: 3.58 | C9: =B9*(25/100) -> 0.895 | D9: =C9+B9 -> 4.475 | E9: 0.41 | I9: 1.26 | L9: =E9*Prices!B$2 -> 45100 | M9: =F9*Prices!C$2 -> 0 | N9: =G9*Prices!D$2 -> 0 | O9: =H9*Prices!E$2 -> 0 | P9: =I9*2000+J9*10000+K9*1800 -> 2520 | Q9: =D9*Prices!A$2 -> 79878.75 | R9: =L9+M9+N9+O9 -> 45100 | S9: =R9+Q9+P9 -> 127498.75 | T9: 8 | U9: Return
A10: 9 | B10: 2.7 | C10: =B10*(25/100) -> 0.675 | D10: =C10+B10 -> 3.375 | E10: 0.56 | L10: =E10*Prices!B$2 -> 61600 | M10: =F10*Prices!C$2 -> 0 | N10: =G10*Prices!D$2 -> 0 | O10: =H10*Prices!E$2 -> 0 | P10: =I10*2000+J10*10000+K10*1800 -> 0 | Q10: =D10*Prices!A$2 -> 60243.75 | R10: =L10+M10+N10+O10 -> 61600 | S10: =R10+Q10+P10 -> 121843.75 | T10: 9 | U10: Available
A11: 10 | B11: 2.694 | C11: =B11*(25/100) -> 0.6735 | D11: =C11+B11 -> 3.3675 | E11: 0.53 | L11: =E11*Prices!B$2 -> 58300 | M11: =F11*Prices!C$2 -> 0 | N11: =G11*Prices!D$2 -> 0 | O11: =H11*Prices!E$2 -> 0 | P11: =I11*2000+J11*10000+K11*1800 -> 0 | Q11: =D11*Prices!A$2 -> 60109.875 | R11: =L11+M11+N11+O11 -> 58300 | S11: =R11+Q11+P11 -> 118409.88 | T11: 10 | U11: Sold
A12: 11 | B12: 3.66 | C12: =B12*(25/100) -> 0.915 | D12: =C12+B12 -> 4.575 | E12: 0.69 | L12: =E12*Prices!B$2 -> 75900 | M12: =F12*Prices!C$2 -> 0 | N12: =G12*Prices!D$2 -> 0 | O12: =H12*Prices!E$2 -> 0 | P12: =I12*2000+J12*10000+K12*1800 -> 0 | Q12: =D12*Prices!A$2 -> 81663.75 | R12: =L12+M12+N12+O12 -> 75900 | S12: =R12+Q12+P12 -> 157563.75 | T12: 11 | U12: Available | V12: A
A13: 12 | B13: 1.568 | C13: =B13*(25/100) -> 0.392 | D13: =C13+B13 -> 1.96 | E13: 0.36 | L13: =E13*Prices!B$2 -> 39600 | M13: =F13*Prices!C$2 -> 0 | N13: =G13*Prices!D$2 -> 0 | O13: =H13*Prices!E$2 -> 0 | P13: =I13*2000+J13*10000+K13*1800 -> 0 | Q13: =D13*Prices!A$2 -> 34986 | R13: =L13+M13+N13+O13 -> 39600 | S13: =R13+Q13+P13 -> 74586 | T13: 12 | U13: Available | V13: A
A14: 13 | B14: 2.48 | C14: =B14*(25/100) -> 0.62 | D14: =C14+B14 -> 3.1 | E14: 0.49 | L14: =E14*Prices!B$2 -> 53900 | M14: =F14*Prices!C$2 -> 0 | N14: =G14*Prices!D$2 -> 0 | O14: =H14*Prices!E$2 -> 0 | P14: =I14*2000+J14*10000+K14*1800 -> 0 | Q14: =D14*Prices!A$2 -> 55335 | R14: =L14+M14+N14+O14 -> 53900 | S14: =R14+Q14+P14 -> 109235 | T14: 13 | U14: Sold
A15: 14 | B15: 2.92 | C15: =B15*(25/100) -> 0.73 | D15: =C15+B15 -> 3.65 | E15: 0.83 | L15: =E15*Prices!B$2 -> 91300 | M15: =F15*Prices!C$2 -> 0 | N15: =G15*Prices!D$2 -> 0 | O15: =H15*Prices!E$2 -> 0 | P15: =I15*2000+J15*10000+K15*1800 -> 0 | Q15: =D15*Prices!A$2 -> 65152.5 | R15: =L15+M15+N15+O15 -> 91300 | S15: =R15+Q15+P15 -> 156452.5 | T15: 14 | U15: Available | V15: A
A16: 15 | B16: 5.11 | C16: =B16*(25/100) -> 1.2775 | D16: =C16+B16 -> 6.3875 | E16: 1.24 | L16: =E16*Prices!B$2 -> 136400 | M16: =F16*Prices!C$2 -> 0 | N16: =G16*Prices!D$2 -> 0 | O16: =H16*Prices!E$2 -> 0 | P16: =I16*2000+J16*10000+K16*1800 -> 0 | Q16: =D16*Prices!A$2 -> 114016.88 | R16: =L16+M16+N16+O16 -> 136400 | S16: =R16+Q16+P16 -> 250416.88 | T16: 15 | U16: Sold
A17: 16 | B17: 3.182 | C17: =B17*(25/100) -> 0.7955 | D17: =C17+B17 -> 3.9775 | E17: 0.79 | L17: =E17*Prices!B$2 -> 86900 | M17: =F17*Prices!C$2 -> 0 | N17: =G17*Prices!D$2 -> 0 | O17: =H17*Prices!E$2 -> 0 | P17: =I17*2000+J17*10000+K17*1800 -> 0 | Q17: =D17*Prices!A$2 -> 70998.375 | R17: =L17+M17+N17+O17 -> 86900 | S17: =R17+Q17+P17 -> 157898.38 | T17: 16 | U17: Sold
A18: 17 | B18: 2.984 | C18: =B18*(25/100) -> 0.746 | D18: =C18+B18 -> 3.73 | E18: 0.88 | L18: =E18*Prices!B$2 -> 96800 | M18: =F18*Prices!C$2 -> 0 | N18: =G18*Prices!D$2 -> 0 | O18: =H18*Prices!E$2 -> 0 | P18: =I18*2000+J18*10000+K18*1800 -> 0 | Q18: =D18*Prices!A$2 -> 66580.5 | R18: =L18+M18+N18+O18 -> 96800 | S18: =R18+Q18+P18 -> 163380.5 | T18: 17 | U18: Available | V18: A
A19: 18 | B19: 3.174 | C19: =B19*(25/100) -> 0.7935 | D19: =C19+B19 -> 3.9675 | E19: 0.68 | L19: =E19*Prices!B$2 -> 74800 | M19: =F19*Prices!C$2 -> 0 | N19: =G19*Prices!D$2 -> 0 | O19: =H19*Prices!E$2 -> 0 | P19: =I19*2000+J19*10000+K19*1800 -> 0 | Q19: =D19*Prices!A$2 -> 70819.875 | R19: =L19+M19+N19+O19 -> 74800 | S19: =R19+Q19+P19 -> 145619.88 | T19: 18 | U19: Sold
A20: 19 | B20: 3.282 | C20: =B20*(25/100) -> 0.8205 | D20: =C20+B20 -> 4.1025 | E20: 0.89 | L20: =E20*Prices!B$2 -> 97900 | M20: =F20*Prices!C$2 -> 0 | N20: =G20*Prices!D$2 -> 0 | O20: =H20*Prices!E$2 -> 0 | P20: =I20*2000+J20*10000+K20*1800 -> 0 | Q20: =D20*Prices!A$2 -> 73229.625 | R20: =L20+M20+N20+O20 -> 97900 | S20: =R20+Q20+P20 -> 171129.62 | T20: 19 | U20: Sold
A21: 20 | B21: 3.786 | C21: =B21*(25/100) -> 0.9465 | D21: =C21+B21 -> 4.7325 | E21: 0.77 | L21: =E21*Prices!B$2 -> 84700 | M21: =F21*Prices!C$2 -> 0 | N21: =G21*Prices!D$2 -> 0 | O21: =H21*Prices!E$2 -> 0 | P21: =I21*2000+J21*10000+K21*1800 -> 0 | Q21: =D21*Prices!A$2 -> 84475.125 | R21: =L21+M21+N21+O21 -> 84700 | S21: =R21+Q21+P21 -> 169175.12 | T21: 20 | U21: Sold
A22: 21 | B22: 1.324 | C22: =B22*(25/100) -> 0.331 | D22: =C22+B22 -> 1.655 | E22: 0.13 | L22: =E22*Prices!B$2 -> 14300 | M22: =F22*Prices!C$2 -> 0 | N22: =G22*Prices!D$2 -> 0 | O22: =H22*Prices!E$2 -> 0 | P22: =I22*2000+J22*10000+K22*1800 -> 0 | Q22: =D22*Prices!A$2 -> 29541.75 | R22: =L22+M22+N22+O22 -> 14300 | S22: =R22+Q22+P22 -> 43841.75 | T22: 21 | U22: Sold
A23: 22 | B23: 3.664 | C23: =B23*(25/100) -> 0.916 | D23: =C23+B23 -> 4.58 | E23: 0.2774 | L23: =E23*Prices!B$2 -> 30514 | M23: =F23*Prices!C$2 -> 0 | N23: =G23*Prices!D$2 -> 0 | O23: =H23*Prices!E$2 -> 0 | P23: =I23*2000+J23*10000+K23*1800 -> 0 | Q23: =D23*Prices!A$2 -> 81753 | R23: =L23+M23+N23+O23 -> 30514 | S23: =R23+Q23+P23 -> 112267 | T23: 22 | U23: Sold
A24: 23 | B24: 2.65 | C24: =B24*(25/100) -> 0.6625 | D24: =C24+B24 -> 3.3125 | E24: 0.46 | L24: =E24*Prices!B$2 -> 50600 | M24: =F24*Prices!C$2 -> 0 | N24: =G24*Prices!D$2 -> 0 | O24: =H24*Prices!E$2 -> 0 | P24: =I24*2000+J24*10000+K24*1800 -> 0 | Q24: =D24*Prices!A$2 -> 59128.125 | R24: =L24+M24+N24+O24 -> 50600 | S24: =R24+Q24+P24 -> 109728.12 | T24: 23 | U24: Sold
A25: 24 | B25: 2.83 | C25: =B25*(25/100) -> 0.7075 | D25: =C25+B25 -> 3.5375 | E25: 0.35 | L25: =E25*Prices!B$2 -> 38500 | M25: =F25*Prices!C$2 -> 0 | N25: =G25*Prices!D$2 -> 0 | O25: =H25*Prices!E$2 -> 0 | P25: =I25*2000+J25*10000+K25*1800 -> 0 | Q25: =D25*Prices!A$2 -> 63144.375 | R25: =L25+M25+N25+O25 -> 38500 | S25: =R25+Q25+P25 -> 101644.38 | T25: 24 | U25: Sold
A26: 25 | B26: 2.564 | C26: =B26*(25/100) -> 0.641 | D26: =C26+B26 -> 3.205 | E26: 0.38 | L26: =E26*Prices!B$2 -> 41800 | M26: =F26*Prices!C$2 -> 0 | N26: =G26*Prices!D$2 -> 0 | O26: =H26*Prices!E$2 -> 0 | P26: =I26*2000+J26*10000+K26*1800 -> 0 | Q26: =D26*Prices!A$2 -> 57209.25 | R26: =L26+M26+N26+O26 -> 41800 | S26: =R26+Q26+P26 -> 99009.25 | T26: 25 | U26: Sold
A27: 26 | B27: 2.706 | C27: =B27*(25/100) -> 0.6765 | D27: =C27+B27 -> 3.3825 | E27: 0.52 | L27: =E27*Prices!B$2 -> 57200 | M27: =F27*Prices!C$2 -> 0 | N27: =G27*Prices!D$2 -> 0 | O27: =H27*Prices!E$2 -> 0 | P27: =I27*2000+J27*10000+K27*1800 -> 0 | Q27: =D27*Prices!A$2 -> 60377.625 | R27: =L27+M27+N27+O27 -> 57200 | S27: =R27+Q27+P27 -> 117577.62 | T27: 26 | U27: Sold
A28: 27 | B28: 2.76 | C28: =B28*(25/100) -> 0.69 | D28: =C28+B28 -> 3.45 | E28: 0.33 | L28: =E28*Prices!B$2 -> 36300 | M28: =F28*Prices!C$2 -> 0 | N28: =G28*Prices!D$2 -> 0 | O28: =H28*Prices!E$2 -> 0 | P28: =I28*2000+J28*10000+K28*1800 -> 0 | Q28: =D28*Prices!A$2 -> 61582.5 | R28: =L28+M28+N28+O28 -> 36300 | S28: =R28+Q28+P28 -> 97882.5 | T28: 27 | U28: Available | V28: A
A29: 28 | B29: 1.904 | C29: =B29*(25/100) -> 0.476 | D29: =C29+B29 -> 2.38 | E29: 0.28 | L29: =E29*Prices!B$2 -> 30800 | M29: =F29*Prices!C$2 -> 0 | N29: =G29*Prices!D$2 -> 0 | O29: =H29*Prices!E$2 -> 0 | P29: =I29*2000+J29*10000+K29*1800 -> 0 | Q29: =D29*Prices!A$2 -> 42483 | R29: =L29+M29+N29+O29 -> 30800 | S29: =R29+Q29+P29 -> 73283 | T29: 28 | U29: Sold
A30: 29 | B30: 9.384 | C30: =B30*(25/100) -> 2.346 | D30: =C30+B30 -> 11.73 | E30: 1.38 | K30: 8 | L30: =E30*Prices!B$2 -> 151800 | M30: =F30*Prices!C$2 -> 0 | N30: =G30*Prices!D$2 -> 0 | O30: =H30*Prices!E$2 -> 0 | P30: =I30*2000+J30*10000+K30*1800 -> 14400 | Q30: =D30*Prices!A$2 -> 209380.5 | R30: =L30+M30+N30+O30 -> 151800 | S30: =R30+Q30+P30 -> 375580.5 | T30: 29 | U30: Available | V30: A
A31: 30 | B31: 7.69 | C31: =B31*(25/100) -> 1.9225 | D31: =C31+B31 -> 9.6125 | E31: 0.98 | K31: 6.42 | L31: =E31*Prices!B$2 -> 107800 | M31: =F31*Prices!C$2 -> 0 | N31: =G31*Prices!D$2 -> 0 | O31: =H31*Prices!E$2 -> 0 | P31: =I31*2000+J31*10000+K31*1800 -> 11556 | Q31: =D31*Prices!A$2 -> 171583.12 | R31: =L31+M31+N31+O31 -> 107800 | S31: =R31+Q31+P31 -> 290939.12 | T31: 30 | U31: Sold
A32: 31 | B32: 4.37 | C32: =B32*(25/100) -> 1.0925 | D32: =C32+B32 -> 5.4625 | E32: 0.54 | K32: 9.96 | L32: =E32*Prices!B$2 -> 59400 | M32: =F32*Prices!C$2 -> 0 | N32: =G32*Prices!D$2 -> 0 | O32: =H32*Prices!E$2 -> 0 | P32: =I32*2000+J32*10000+K32*1800 -> 17928 | Q32: =D32*Prices!A$2 -> 97505.625 | R32: =L32+M32+N32+O32 -> 59400 | S32: =R32+Q32+P32 -> 174833.62 | T32: 31 | U32: Sold
A33: 32 | B33: 6.42 | C33: =B33*(25/100) -> 1.605 | D33: =C33+B33 -> 8.025 | E33: 0.95 | L33: =E33*Prices!B$2 -> 104500 | M33: =F33*Prices!C$2 -> 0 | N33: =G33*Prices!D$2 -> 0 | O33: =H33*Prices!E$2 -> 0 | P33: =I33*2000+J33*10000+K33*1800 -> 0 | Q33: =D33*Prices!A$2 -> 143246.25 | R33: =L33+M33+N33+O33 -> 104500 | S33: =R33+Q33+P33 -> 247746.25 | T33: 32 | U33: Sold
A34: 33 | B34: 3.194 | C34: =B34*(25/100) -> 0.7985 | D34: =C34+B34 -> 3.9925 | E34: 0.7 | F34: 0.08 | L34: =E34*Prices!B$2 -> 77000 | M34: =F34*Prices!C$2 -> 12800 | N34: =G34*Prices!D$2 -> 0 | O34: =H34*Prices!E$2 -> 0 | P34: =I34*2000+J34*10000+K34*1800 -> 0 | Q34: =D34*Prices!A$2 -> 71266.125 | R34: =L34+M34+N34+O34 -> 89800 | S34: =R34+Q34+P34 -> 161066.12 | T34: 33 | U34: Sold
A35: 34 | B35: 4.4 | C35: =B35*(25/100) -> 1.1 | D35: =C35+B35 -> 5.5 | E35: 1.22 | L35: =E35*Prices!B$2 -> 134200 | M35: =F35*Prices!C$2 -> 0 | N35: =G35*Prices!D$2 -> 0 | O35: =H35*Prices!E$2 -> 0 | P35: =I35*2000+J35*10000+K35*1800 -> 0 | Q35: =D35*Prices!A$2 -> 98175 | R35: =L35+M35+N35+O35 -> 134200 | S35: =R35+Q35+P35 -> 232375 | T35: 34 | U35: Available | V35: A
A36: 35 | B36: 4.31 | C36: =B36*(25/100) -> 1.0775 | D36: =C36+B36 -> 5.3875 | E36: 0.6 | J36: 0.7 | L36: =E36*Prices!B$2 -> 66000 | M36: =F36*Prices!C$2 -> 0 | N36: =G36*Prices!D$2 -> 0 | O36: =H36*Prices!E$2 -> 0 | P36: =I36*2000+J36*10000+K36*1800 -> 7000 | Q36: =D36*Prices!A$2 -> 96166.875 | R36: =L36+M36+N36+O36 -> 66000 | S36: =R36+Q36+P36 -> 169166.88 | T36: 35 | U36: Available | V36: A
A37: 36 | B37: 8.02 | C37: =B37*(25/100) -> 2.005 | D37: =C37+B37 -> 10.025 | E37: 0.96 | J37: 2.68 | L37: =E37*Prices!B$2 -> 105600 | M37: =F37*Prices!C$2 -> 0 | N37: =G37*Prices!D$2 -> 0 | O37: =H37*Prices!E$2 -> 0 | P37: =I37*2000+J37*10000+K37*1800 -> 26800 | Q37: =D37*Prices!A$2 -> 178946.25 | R37: =L37+M37+N37+O37 -> 105600 | S37: =R37+Q37+P37 -> 311346.25 | T37: 36 | U37: Sold
A38: 37 | B38: 3.8 | C38: =B38*(25/100) -> 0.95 | D38: =C38+B38 -> 4.75 | E38: 0.33 | J38: 1.1 | L38: =E38*Prices!B$2 -> 36300 | M38: =F38*Prices!C$2 -> 0 | N38: =G38*Prices!D$2 -> 0 | O38: =H38*Prices!E$2 -> 0 | P38: =I38*2000+J38*10000+K38*1800 -> 11000 | Q38: =D38*Prices!A$2 -> 84787.5 | R38: =L38+M38+N38+O38 -> 36300 | S38: =R38+Q38+P38 -> 132087.5 | T38: 37 | U38: Available | V38: A
A39: 38 | B39: 5.562 | C39: =B39*(25/100) -> 1.3905 | D39: =C39+B39 -> 6.9525 | E39: 1.16 | J39: 1.63 | L39: =E39*Prices!B$2 -> 127600 | M39: =F39*Prices!C$2 -> 0 | N39: =G39*Prices!D$2 -> 0 | O39: =H39*Prices!E$2 -> 0 | P39: =I39*2000+J39*10000+K39*1800 -> 16300 | Q39: =D39*Prices!A$2 -> 124102.12 | R39: =L39+M39+N39+O39 -> 127600 | S39: =R39+Q39+P39 -> 268002.12 | T39: 38 | U39: Sold
A40: 39 | B40: 2.66 | C40: =B40*(25/100) -> 0.665 | D40: =C40+B40 -> 3.325 | H40: 0.71 | L40: =E40*Prices!B$2 -> 0 | M40: =F40*Prices!C$2 -> 0 | N40: =G40*Prices!D$2 -> 0 | O40: =H40*360000 -> 255600 | P40: =I40*2000+J40*10000+K40*1800 -> 0 | Q40: =D40*Prices!A$2 -> 59351.25 | R40: =L40+M40+N40+O40 -> 255600 | S40: =R40+Q40+P40 -> 314951.25 | T40: 39 | U40: Available | V40: A
...

Sheet Gents Ring
A1: Sn | B1: Net Weight | C1: Wstg + MC | D1: Gross Weight | E1: Dmd <0.06 | F1: Dmd < 0.12 | G1: Dmd <0.17 | H1: Dmd Big | I1: Ruby | J1: Emreld | K1: Muga | L1: Dmd Price | M1: Dmd Price | N1: Dmd Price | O1: Dmd Price | P1: Stn Price | Q1: Gold Price | R1: Ttl dmd Price | S1: Total Price | T1: Sn
A2: 1 | B2: 5.478 | C2: =B2*(25/100) -> 1.3695 | D2: =C2+B2 -> 6.8475 | E2: =0.63+0.08 -> 0.71 | L2: =E2*60000 -> 42600 | M2: =F2*70000 -> 0 | N2: =G2*90000 -> 0 | O2: =H2*200000 -> 0 | P2: =I2*2000+J2*4000+K2*650 -> 0 | Q2: =D2*6700 -> 45878.25 | R2: =L2+M2+N2+O2 -> 42600 | S2: =R2+Q2+P2 -> 88478.25 | T2: 1 | U2: Return
A3: 2 | B3: 6.094 | C3: =B3*(25/100) -> 1.5235 | D3: =C3+B3 -> 7.6175 | H3: 0.53 | L3: =E3*Prices!B$2 -> 0 | M3: =F3*Prices!C$2 -> 0 | N3: =G3*Prices!D$2 -> 0 | O3: =H3*Prices!E$2 -> 185500 | P3: =I3*2000+J3*4000+K3*650 -> 0 | Q3: =D3*Prices!A$2 -> 135972.38 | R3: =L3+M3+N3+O3 -> 185500 | S3: =R3+Q3+P3 -> 321472.38 | T3: 2 | U3: Available | V3: A
A4: 3 | B4: 6.94 | C4: =B4*(25/100) -> 1.735 | D4: =C4+B4 -> 8.675 | H4: 0.27 | L4: =E4*Prices!B$2 -> 0 | M4: =F4*Prices!C$2 -> 0 | N4: =G4*Prices!D$2 -> 0 | O4: =H4*200000 -> 54000 | P4: =I4*2000+J4*4000+K4*650 -> 0 | Q4: =D4*Prices!A$2 -> 154848.75 | R4: =L4+M4+N4+O4 -> 54000 | S4: =R4+Q4+P4 -> 208848.75 | T4: 3 | U4: Sold
A5: 4 | B5: 3.694 | C5: =B5*(25/100) -> 0.9235 | D5: =C5+B5 -> 4.6175 | E5: 0.46 | L5: =E5*Prices!B$2 -> 50600 | M5: =F5*Prices!C$2 -> 0 | N5: =G5*Prices!D$2 -> 0 | O5: =H5*Prices!E$2 -> 0 | P5: =I5*2000+J5*4000+K5*650 -> 0 | Q5: =D5*Prices!A$2 -> 82422.375 | R5: =L5+M5+N5+O5 -> 50600 | S5: =R5+Q5+P5 -> 133022.38 | T5: 4 | U5: Sold
A6: 5 | B6: 4.15 | C6: =B6*(25/100) -> 1.0375 | D6: =C6+B6 -> 5.1875 | F6: 0.7 | L6: =E6*Prices!B$2 -> 0 | M6: =F6*Prices!C$2 -> 112000 | N6: =G6*Prices!D$2 -> 0 | O6: =H6*Prices!E$2 -> 0 | P6: =I6*2000+J6*4000+K6*650 -> 0 | Q6: =D6*Prices!A$2 -> 92596.875 | R6: =L6+M6+N6+O6 -> 112000 | S6: =R6+Q6+P6 -> 204596.88 | T6: 5 | U6: Available | V6: A
A7: 6 | B7: 3.284 | C7: =B7*(25/100) -> 0.821 | D7: =C7+B7 -> 4.105 | E7: 0.58 | L7: =E7*Prices!B$2 -> 63800 | M7: =F7*Prices!C$2 -> 0 | N7: =G7*Prices!D$2 -> 0 | O7: =H7*Prices!E$2 -> 0 | P7: =I7*2000+J7*4000+K7*650 -> 0 | Q7: =D7*Prices!A$2 -> 73274.25 | R7: =L7+M7+N7+O7 -> 63800 | S7: =R7+Q7+P7 -> 137074.25 | T7: 6 | U7: Available | V7: A
A8: 7 | B8: 5.862 | C8: =B8*(25/100) -> 1.4655 | D8: =C8+B8 -> 7.3275 | H8: 0.39 | L8: =E8*Prices!B$2 -> 0 | M8: =F8*Prices!C$2 -> 0 | N8: =G8*Prices!D$2 -> 0 | O8: =H8*Prices!E$2 -> 136500 | P8: =I8*2000+J8*4000+K8*650 -> 0 | Q8: =D8*Prices!A$2 -> 130795.88 | R8: =L8+M8+N8+O8 -> 136500 | S8: =R8+Q8+P8 -> 267295.88 | T8: 7 | U8: Available | V8: A
A9: 8 | B9: 5.638 | C9: =B9*(25/100) -> 1.4095 | D9: =C9+B9 -> 7.0475 | H9: 0.56 | L9: =E9*Prices!B$2 -> 0 | M9: =F9*Prices!C$2 -> 0 | N9: =G9*Prices!D$2 -> 0 | O9: =H9*180000 -> 100800 | P9: =I9*2000+J9*4000+K9*650 -> 0 | Q9: =D9*Prices!A$2 -> 125797.88 | R9: =L9+M9+N9+O9 -> 100800 | S9: =R9+Q9+P9 -> 226597.88 | T9: 8 | U9: Available | V9: A
A10: 9 | B10: 4.424 | C10: =B10*(25/100) -> 1.106 | D10: =C10+B10 -> 5.53 | E10: 0.48 | L10: =E10*Prices!B$2 -> 52800 | M10: =F10*Prices!C$2 -> 0 | N10: =G10*Prices!D$2 -> 0 | O10: =H10*Prices!E$2 -> 0 | P10: =I10*2000+J10*4000+K10*650 -> 0 | Q10: =D10*Prices!A$2 -> 98710.5 | R10: =L10+M10+N10+O10 -> 52800 | S10: =R10+Q10+P10 -> 151510.5 | T10: 9 | U10: Sold
A11: 10 | B11: 3.408 | C11: =B11*(25/100) -> 0.852 | D11: =C11+B11 -> 4.26 | E11: 0.51 | L11: =E11*Prices!B$2 -> 56100 | M11: =F11*Prices!C$2 -> 0 | N11: =G11*Prices!D$2 -> 0 | O11: =H11*Prices!E$2 -> 0 | P11: =I11*2000+J11*4000+K11*650 -> 0 | Q11: =D11*Prices!A$2 -> 76041 | R11: =L11+M11+N11+O11 -> 56100 | S11: =R11+Q11+P11 -> 132141 | T11: 10 | U11: Sold
A12: 11 | B12: 3.066 | C12: =B12*(25/100) -> 0.7665 | D12: =C12+B12 -> 3.8325 | E12: 0.47 | L12: =E12*Prices!B$2 -> 51700 | M12: =F12*Prices!C$2 -> 0 | N12: =G12*Prices!D$2 -> 0 | O12: =H12*Prices!E$2 -> 0 | P12: =I12*2000+J12*4000+K12*650 -> 0 | Q12: =D12*Prices!A$2 -> 68410.125 | R12: =L12+M12+N12+O12 -> 51700 | S12: =R12+Q12+P12 -> 120110.12 | T12: 11 | U12: Available | V12: A
A13: 12 | B13: 4.904 | C13: =B13*(25/100) -> 1.226 | D13: =C13+B13 -> 6.13 | E13: 0.28 | L13: =E13*Prices!B$2 -> 30800 | M13: =F13*Prices!C$2 -> 0 | N13: =G13*Prices!D$2 -> 0 | O13: =H13*Prices!E$2 -> 0 | P13: =I13*2000+J13*4000+K13*650 -> 0 | Q13: =D13*Prices!A$2 -> 109420.5 | R13: =L13+M13+N13+O13 -> 30800 | S13: =R13+Q13+P13 -> 140220.5 | T13: 12 | U13: Sold
A14: 13 | B14: 5.922 | C14: =B14*(25/100) -> 1.4805 | D14: =C14+B14 -> 7.4025 | G14: 0.79 | L14: =E14*Prices!B$2 -> 0 | M14: =F14*Prices!C$2 -> 0 | N14: =G14*Prices!D$2 -> 154050 | O14: =H14*Prices!E$2 -> 0 | P14: =I14*2000+J14*4000+K14*650 -> 0 | Q14: =D14*Prices!A$2 -> 132134.62 | R14: =L14+M14+N14+O14 -> 154050 | S14: =R14+Q14+P14 -> 286184.62 | T14: 13 | U14: Sold
A15: 14 | B15: 6.126 | C15: =B15*(25/100) -> 1.5315 | D15: =C15+B15 -> 7.6575 | G15: 0.77 | L15: =E15*Prices!B$2 -> 0 | M15: =F15*Prices!C$2 -> 0 | N15: =G15*Prices!D$2 -> 150150 | O15: =H15*Prices!E$2 -> 0 | P15: =I15*2000+J15*4000+K15*650 -> 0 | Q15: =D15*Prices!A$2 -> 136686.38 | R15: =L15+M15+N15+O15 -> 150150 | S15: =R15+Q15+P15 -> 286836.38 | T15: 14 | U15: Sold
A16: 15 | B16: 6.334 | C16: =B16*(25/100) -> 1.5835 | D16: =C16+B16 -> 7.9175 | E16: 0.48 | L16: =E16*Prices!B$2 -> 52800 | M16: =F16*Prices!C$2 -> 0 | N16: =G16*Prices!D$2 -> 0 | O16: =H16*Prices!E$2 -> 0 | P16: =I16*2000+J16*4000+K16*650 -> 0 | Q16: =D16*Prices!A$2 -> 141327.38 | R16: =L16+M16+N16+O16 -> 52800 | S16: =R16+Q16+P16 -> 194127.38 | T16: 15 | U16: Sold
A17: 16 | B17: 6.466 | C17: =B17*(25/100) -> 1.6165 | D17: =C17+B17 -> 8.0825 | E17: 0.47 | L17: =E17*Prices!B$2 -> 51700 | M17: =F17*Prices!C$2 -> 0 | N17: =G17*Prices!D$2 -> 0 | O17: =H17*Prices!E$2 -> 0 | P17: =I17*2000+J17*4000+K17*650 -> 0 | Q17: =D17*Prices!A$2 -> 144272.62 | R17: =L17+M17+N17+O17 -> 51700 | S17: =R17+Q17+P17 -> 195972.62 | T17: 16 | U17: Sold
A18: 17 | B18: 4.352 | C18: =B18*(25/100) -> 1.088 | D18: =C18+B18 -> 5.44 | E18: 0.34 | L18: =E18*Prices!B$2 -> 37400 | M18: =F18*Prices!C$2 -> 0 | N18: =G18*Prices!D$2 -> 0 | O18: =H18*Prices!E$2 -> 0 | P18: =I18*2000+J18*4000+K18*650 -> 0 | Q18: =D18*Prices!A$2 -> 97104 | R18: =L18+M18+N18+O18 -> 37400 | S18: =R18+Q18+P18 -> 134504 | T18: 17 | U18: Available | V18: A
A19: 18 | B19: 6.66 | C19: =B19*(25/100) -> 1.665 | D19: =C19+B19 -> 8.325 | F19: 0.68 | L19: =E19*Prices!B$2 -> 0 | M19: =F19*Prices!C$2 -> 108800 | N19: =G19*Prices!D$2 -> 0 | O19: =H19*Prices!E$2 -> 0 | P19: =I19*2000+J19*4000+K19*650 -> 0 | Q19: =D19*Prices!A$2 -> 148601.25 | R19: =L19+M19+N19+O19 -> 108800 | S19: =R19+Q19+P19 -> 257401.25 | T19: 18 | U19: Available | V19: A
A20: 19 | B20: 6.624 | C20: =B20*(25/100) -> 1.656 | D20: =C20+B20 -> 8.28 | E20: 0.48 | L20: =E20*Prices!B$2 -> 52800 | M20: =F20*Prices!C$2 -> 0 | N20: =G20*Prices!D$2 -> 0 | O20: =H20*Prices!E$2 -> 0 | P20: =I20*2000+J20*4000+K20*650 -> 0 | Q20: =D20*Prices!A$2 -> 147798 | R20: =L20+M20+N20+O20 -> 52800 | S20: =R20+Q20+P20 -> 200598 | T20: 19 | U20: Sold
A21: 20 | B21: 5.492 | C21: =B21*(25/100) -> 1.373 | D21: =C21+B21 -> 6.865 | E21: 0.39 | L21: =E21*Prices!B$2 -> 42900 | M21: =F21*Prices!C$2 -> 0 | N21: =G21*Prices!D$2 -> 0 | O21: =H21*Prices!E$2 -> 0 | P21: =I21*2000+J21*4000+K21*650 -> 0 | Q21: =D21*Prices!A$2 -> 122540.25 | R21: =L21+M21+N21+O21 -> 42900 | S21: =R21+Q21+P21 -> 165440.25 | T21: 20 | U21: Sold
A22: 21 | B22: 5.552 | C22: =B22*(25/100) -> 1.388 | D22: =C22+B22 -> 6.94 | E22: 0.39 | L22: =E22*Prices!B$2 -> 42900 | M22: =F22*Prices!C$2 -> 0 | N22: =G22*Prices!D$2 -> 0 | O22: =H22*Prices!E$2 -> 0 | P22: =I22*2000+J22*4000+K22*650 -> 0 | Q22: =D22*Prices!A$2 -> 123879 | R22: =L22+M22+N22+O22 -> 42900 | S22: =R22+Q22+P22 -> 166779 | T22: 21 | U22: Sold
A23: 22 | B23: 6.114 | C23: =B23*(25/100) -> 1.5285 | D23: =C23+B23 -> 7.6425 | G23: 0.58 | L23: =E23*Prices!B$2 -> 0 | M23: =F23*Prices!C$2 -> 0 | N23: =G23*Prices!D$2 -> 113100 | O23: =H23*Prices!E$2 -> 0 | P23: =I23*2000+J23*4000+K23*650 -> 0 | Q23: =D23*Prices!A$2 -> 136418.62 | R23: =L23+M23+N23+O23 -> 113100 | S23: =R23+Q23+P23 -> 249518.62 | T23: 22 | U23: Available | V23: A
A24: 23 | B24: 5.052 | C24: =B24*(25/100) -> 1.263 | D24: =C24+B24 -> 6.315 | H24: 0.69 | L24: =E24*Prices!B$2 -> 0 | M24: =F24*Prices!C$2 -> 0 | N24: =G24*Prices!D$2 -> 0 | O24: =H24*180000 -> 124200 | P24: =I24*2000+J24*4000+K24*650 -> 0 | Q24: =D24*Prices!A$2 -> 112722.75 | R24: =L24+M24+N24+O24 -> 124200 | S24: =R24+Q24+P24 -> 236922.75 | T24: 23 | U24: Available | V24: A
A25: 24 | B25: 4.84 | C25: =B25*(25/100) -> 1.21 | D25: =C25+B25 -> 6.05 | G25: 0.85 | L25: =E25*Prices!B$2 -> 0 | M25: =F25*Prices!C$2 -> 0 | N25: =G25*Prices!D$2 -> 165750 | O25: =H25*Prices!E$2 -> 0 | P25: =I25*2000+J25*4000+K25*650 -> 0 | Q25: =D25*Prices!A$2 -> 107992.5 | R25: =L25+M25+N25+O25 -> 165750 | S25: =R25+Q25+P25 -> 273742.5 | T25: 24 | U25: Available | V25: A
A26: 25 | B26: 5.75 | C26: =B26*(25/100) -> 1.4375 | D26: =C26+B26 -> 7.1875 | E26: 0.69 | L26: =E26*Prices!B$2 -> 75900 | M26: =F26*Prices!C$2 -> 0 | N26: =G26*Prices!D$2 -> 0 | O26: =H26*Prices!E$2 -> 0 | P26: =I26*2000+J26*4000+K26*650 -> 0 | Q26: =D26*Prices!A$2 -> 128296.88 | R26: =L26+M26+N26+O26 -> 75900 | S26: =R26+Q26+P26 -> 204196.88 | T26: 25 | U26: Sold
A27: 26 | B27: 7.27 | C27: =B27*(25/100) -> 1.8175 | D27: =C27+B27 -> 9.0875 | E27: 0.2 | L27: =E27*Prices!B$2 -> 22000 | M27: =F27*Prices!C$2 -> 0 | N27: =G27*Prices!D$2 -> 0 | O27: =H27*Prices!E$2 -> 0 | P27: =I27*2000+J27*4000+K27*650 -> 0 | Q27: =D27*(Prices!A$2+2200) -> 182204.38 | R27: =L27+M27+N27+O27 -> 22000 | S27: =R27+Q27+P27 -> 204204.38 | T27: 26 | U27: Available | V27: A
A28: 27 | B28: 6.94 | C28: =B28*(25/100) -> 1.735 | D28: =C28+B28 -> 8.675 | H28: 0.54 | L28: =E28*Prices!B$2 -> 0 | M28: =F28*Prices!C$2 -> 0 | N28: =G28*Prices!D$2 -> 0 | O28: =H28*Prices!E$2 -> 189000 | P28: =I28*2000+J28*4000+K28*650 -> 0 | Q28: =D28*Prices!A$2 -> 154848.75 | R28: =L28+M28+N28+O28 -> 189000 | S28: =R28+Q28+P28 -> 343848.75 | T28: 27 | U28: Available | V28: A
A29: 28 | B29: 6.1 | C29: =B29*(25/100) -> 1.525 | D29: =C29+B29 -> 7.625 | E29: 0.3 | L29: =E29*Prices!B$2 -> 33000 | M29: =F29*Prices!C$2 -> 0 | N29: =G29*Prices!D$2 -> 0 | O29: =H29*Prices!E$2 -> 0 | P29: =I29*2000+J29*4000+K29*650 -> 0 | Q29: =D29*Prices!A$2 -> 136106.25 | R29: =L29+M29+N29+O29 -> 33000 | S29: =R29+Q29+P29 -> 169106.25 | T29: 28 | U29: Sold
A30: 29 | B30: 4.556 | C30: =B30*(25/100) -> 1.139 | D30: =C30+B30 -> 5.695 | E30: 0.58 | L30: =E30*Prices!B$2 -> 63800 | M30: =F30*Prices!C$2 -> 0 | N30: =G30*Prices!D$2 -> 0 | O30: =H30*Prices!E$2 -> 0 | P30: =I30*2000+J30*4000+K30*650 -> 0 | Q30: =D30*Prices!A$2 -> 101655.75 | R30: =L30+M30+N30+O30 -> 63800 | S30: =R30+Q30+P30 -> 165455.75 | T30: 29 | U30: Sold
A31: 30 | B31: 4.218 | C31: =B31*(25/100) -> 1.0545 | D31: =C31+B31 -> 5.2725 | E31: 0.42 | L31: =E31*Prices!B$2 -> 46200 | M31: =F31*Prices!C$2 -> 0 | N31: =G31*Prices!D$2 -> 0 | O31: =H31*Prices!E$2 -> 0 | P31: =I31*2000+J31*4000+K31*650 -> 0 | Q31: =D31*Prices!A$2 -> 94114.125 | R31: =L31+M31+N31+O31 -> 46200 | S31: =R31+Q31+P31 -> 140314.12 | T31: 30 | U31: Available | V31: A
A32: 31 | B32: 4.428 | C32: =B32*(25/100) -> 1.107 | D32: =C32+B32 -> 5.535 | E32: 0.57 | L32: =E32*Prices!B$2 -> 62700 | M32: =F32*Prices!C$2 -> 0 | N32: =G32*Prices!D$2 -> 0 | O32: =H32*Prices!E$2 -> 0 | P32: =I32*2000+J32*4000+K32*650 -> 0 | Q32: =D32*Prices!A$2 -> 98799.75 | R32: =L32+M32+N32+O32 -> 62700 | S32: =R32+Q32+P32 -> 161499.75 | T32: 31 | U32: Sold
A33: 32 | B33: 4.928 | C33: =B33*(25/100) -> 1.232 | D33: =C33+B33 -> 6.16 | E33: 0.67 | L33: =E33*Prices!B$2 -> 73700 | M33: =F33*Prices!C$2 -> 0 | N33: =G33*Prices!D$2 -> 0 | O33: =H33*Prices!E$2 -> 0 | P33: =I33*2000+J33*4000+K33*650 -> 0 | Q33: =D33*Prices!A$2 -> 109956 | R33: =L33+M33+N33+O33 -> 73700 | S33: =R33+Q33+P33 -> 183656 | T33: 32 | U33: Sold
A34: 33 | B34: 4.62 | C34: =B34*(25/100) -> 1.155 | D34: =C34+B34 -> 5.775 | E34: 0.56 | L34: =E34*Prices!B$2 -> 61600 | M34: =F34*Prices!C$2 -> 0 | N34: =G34*Prices!D$2 -> 0 | O34: =H34*Prices!E$2 -> 0 | P34: =I34*2000+J34*4000+K34*650 -> 0 | Q34: =D34*Prices!A$2 -> 103083.75 | R34: =L34+M34+N34+O34 -> 61600 | S34: =R34+Q34+P34 -> 164683.75 | T34: 33 | U34: Available | V34: A
A35: 34 | B35: 5.448 | C35: =B35*(25/100) -> 1.362 | D35: =C35+B35 -> 6.81 | E35: 0.57 | L35: =E35*Prices!B$2 -> 62700 | M35: =F35*Prices!C$2 -> 0 | N35: =G35*Prices!D$2 -> 0 | O35: =H35*Prices!E$2 -> 0 | P35: =I35*2000+J35*4000+K35*650 -> 0 | Q35: =D35*Prices!A$2 -> 121558.5 | R35: =L35+M35+N35+O35 -> 62700 | S35: =R35+Q35+P35 -> 184258.5 | T35: 34 | U35: Sold
A36: 35 | B36: 5.298 | C36: =B36*(25/100) -> 1.3245 | D36: =C36+B36 -> 6.6225 | E36: 0.72 | L36: =E36*Prices!B$2 -> 79200 | M36: =F36*Prices!C$2 -> 0 | N36: =G36*Prices!D$2 -> 0 | O36: =H36*Prices!E$2 -> 0 | P36: =I36*2000+J36*4000+K36*650 -> 0 | Q36: =D36*Prices!A$2 -> 118211.62 | R36: =L36+M36+N36+O36 -> 79200 | S36: =R36+Q36+P36 -> 197411.62 | T36: 35 | U36: Available | V36: A
A37: 36 | B37: 5.208 | C37: =B37*(25/100) -> 1.302 | D37: =C37+B37 -> 6.51 | E37: 0.57 | L37: =E37*Prices!B$2 -> 62700 | M37: =F37*Prices!C$2 -> 0 | N37: =G37*Prices!D$2 -> 0 | O37: =H37*Prices!E$2 -> 0 | P37: =I37*2000+J37*4000+K37*650 -> 0 | Q37: =D37*Prices!A$2 -> 116203.5 | R37: =L37+M37+N37+O37 -> 62700 | S37: =R37+Q37+P37 -> 178903.5 | T37: 36 | U37: Sold
A38: 37 | B38: 4.738 | C38: =B38*(25/100) -> 1.1845 | D38: =C38+B38 -> 5.9225 | E38: 0.52 | L38: =E38*Prices!B$2 -> 57200 | M38: =F38*Prices!C$2 -> 0 | N38: =G38*Prices!D$2 -> 0 | O38: =H38*Prices!E$2 -> 0 | P38: =I38*2000+J38*4000+K38*650 -> 0 | Q38: =D38*Prices!A$2 -> 105716.62 | R38: =L38+M38+N38+O38 -> 57200 | S38: =R38+Q38+P38 -> 162916.62 | T38: 37 | U38: Sold
A39: 38 | B39: 5.168 | C39: =B39*(25/100) -> 1.292 | D39: =C39+B39 -> 6.46 | E39: 0.62 | L39: =E39*Prices!B$2 -> 68200 | M39: =F39*Prices!C$2 -> 0 | N39: =G39*Prices!D$2 -> 0 | O39: =H39*Prices!E$2 -> 0 | P39: =I39*2000+J39*4000+K39*650 -> 0 | Q39: =D39*Prices!A$2 -> 115311 | R39: =L39+M39+N39+O39 -> 68200 | S39: =R39+Q39+P39 -> 183511 | T39: 38 | U39: Sold
A40: 39 | B40: 3.692 | C40: =B40*(25/100) -> 0.923 | D40: =C40+B40 -> 4.615 | G40: 0.69 | L40: =E40*Prices!B$2 -> 0 | M40: =F40*Prices!C$2 -> 0 | N40: =G40*Prices!D$2 -> 134550 | O40: =H40*Prices!E$2 -> 0 | P40: =I40*2000+J40*4000+K40*650 -> 0 | Q40: =D40*Prices!A$2 -> 82377.75 | R40: =L40+M40+N40+O40 -> 134550 | S40: =R40+Q40+P40 -> 216927.75 | T40: 39 | U40: Available | V40: A
...

Sheet Top
A1: Sn | B1: Net Weightt | C1: Wstg + MC | D1: Gross weight | E1: Dmd <0.06 | F1: Dmd < 0.12 | G1: Dmd <0.17 | H1: Dmd Big | I1: Ruby | J1: Emreld | K1: Muga | L1: Dmd Price | M1: Dmd Price | N1: Dmd Price | O1: Dmd Price | P1: Stn Price | Q1: Gold Price | R1: Ttl dmd Price | S1: Total Price | T1: Sn
A2: 1 | B2: 6.558 | C2: =B2*(25/100) -> 1.6395 | D2: =C2+B2 -> 8.1975 | E2: 0.96 | K2: 6.1 | L2: =E2*Prices!B$2 -> 105600 | M2: =F2*Prices!C$2 -> 0 | N2: =G2*Prices!D$2 -> 0 | O2: =H2*Prices!E$2 -> 0 | P2: =I2*2000+J2*10000+K2*1800 -> 10980 | Q2: =D2*Prices!A$2 -> 146325.38 | R2: =L2+M2+N2+O2 -> 105600 | S2: =R2+Q2+P2 -> 262905.38 | T2: 1 | U2: Return
A3: 2 | B3: 5.89 | C3: =B3*(25/100) -> 1.4725 | D3: =C3+B3 -> 7.3625 | E3: 0.84 | K3: 4.19 | L3: =E3*Prices!B$2 -> 92400 | M3: =F3*Prices!C$2 -> 0 | N3: =G3*Prices!D$2 -> 0 | O3: =H3*Prices!E$2 -> 0 | P3: =I3*2000+J3*10000+K3*1800 -> 7542 | Q3: =D3*Prices!A$2 -> 131420.62 | R3: =L3+M3+N3+O3 -> 92400 | S3: =R3+Q3+P3 -> 231362.62 | T3: 2 | U3: Return
A4: 3 | B4: 2.902 | C4: =B4*(25/100) -> 0.7255 | D4: =C4+B4 -> 3.6275 | E4: 0.64 | L4: =E4*Prices!B$2 -> 70400 | M4: =F4*Prices!C$2 -> 0 | N4: =G4*Prices!D$2 -> 0 | O4: =H4*Prices!E$2 -> 0 | P4: =I4*2000+J4*10000+K4*1800 -> 0 | Q4: =D4*Prices!A$2 -> 64750.875 | R4: =L4+M4+N4+O4 -> 70400 | S4: =R4+Q4+P4 -> 135150.88 | T4: 3 | U4: Available | V4: A
A5: 4 | B5: 3.04 | C5: =B5*(25/100) -> 0.76 | D5: =C5+B5 -> 3.8 | F5: 0.95 | L5: =E5*Prices!B$2 -> 0 | M5: =F5*Prices!C$2 -> 152000 | N5: =G5*Prices!D$2 -> 0 | O5: =H5*Prices!E$2 -> 0 | P5: =I5*2000+J5*10000+K5*1800 -> 0 | Q5: =D5*Prices!A$2 -> 67830 | R5: =L5+M5+N5+O5 -> 152000 | S5: =R5+Q5+P5 -> 219830 | T5: 4 | U5: Available | V5: A
A6: 5 | B6: 3.936 | C6: =B6*(25/100) -> 0.984 | D6: =C6+B6 -> 4.92 | E6: 0.65 | G6: 0.32 | L6: =E6*Prices!B$2 -> 71500 | M6: =F6*Prices!C$2 -> 0 | N6: =G6*Prices!D$2 -> 62400 | O6: =H6*Prices!E$2 -> 0 | P6: =I6*2000+J6*10000+K6*1800 -> 0 | Q6: =D6*Prices!A$2 -> 87822 | R6: =L6+M6+N6+O6 -> 133900 | S6: =R6+Q6+P6 -> 221722 | T6: 5 | U6: Available | V6: A
A7: 6 | B7: 5.382 | C7: =B7*(25/100) -> 1.3455 | D7: =C7+B7 -> 6.7275 | E7: =0.4+0.29 -> 0.69 | L7: =E7*Prices!B$2 -> 75900 | M7: =F7*Prices!C$2 -> 0 | N7: =G7*Prices!D$2 -> 0 | O7: =H7*Prices!E$2 -> 0 | P7: =I7*2000+J7*10000+K7*1800 -> 0 | Q7: =D7*Prices!A$2 -> 120085.88 | R7: =L7+M7+N7+O7 -> 75900 | S7: =R7+Q7+P7 -> 195985.88 | T7: 6 | U7: Sold
A8: 7 | B8: 3.078 | C8: =B8*(25/100) -> 0.7695 | D8: =C8+B8 -> 3.8475 | E8: 0.56 | L8: =E8*Prices!B$2 -> 61600 | M8: =F8*Prices!C$2 -> 0 | N8: =G8*Prices!D$2 -> 0 | O8: =H8*Prices!E$2 -> 0 | P8: =I8*2000+J8*10000+K8*1800 -> 0 | Q8: =D8*Prices!A$2 -> 68677.875 | R8: =L8+M8+N8+O8 -> 61600 | S8: =R8+Q8+P8 -> 130277.88 | T8: 7 | U8: Sold
A9: 8 | B9: 3.996 | C9: =B9*(25/100) -> 0.999 | D9: =C9+B9 -> 4.995 | E9: =0.66+0.21 -> 0.87 | L9: =E9*Prices!B$2 -> 95700 | M9: =F9*Prices!C$2 -> 0 | N9: =G9*Prices!D$2 -> 0 | O9: =H9*Prices!E$2 -> 0 | P9: =I9*2000+J9*10000+K9*1800 -> 0 | Q9: =D9*Prices!A$2 -> 89160.75 | R9: =L9+M9+N9+O9 -> 95700 | S9: =R9+Q9+P9 -> 184860.75 | T9: 8 | U9: Sold
A10: 9 | B10: 2.502 | C10: =B10*(25/100) -> 0.6255 | D10: =C10+B10 -> 3.1275 | E10: 0.44 | L10: =E10*Prices!B$2 -> 48400 | M10: =F10*Prices!C$2 -> 0 | N10: =G10*Prices!D$2 -> 0 | O10: =H10*Prices!E$2 -> 0 | P10: =I10*2000+J10*10000+K10*1800 -> 0 | Q10: =D10*Prices!A$2 -> 55825.875 | R10: =L10+M10+N10+O10 -> 48400 | S10: =R10+Q10+P10 -> 104225.88 | T10: 9 | U10: Sold
A11: 10 | B11: 1.908 | C11: =B11*(25/100) -> 0.477 | D11: =C11+B11 -> 2.385 | E11: 0.36 | L11: =E11*Prices!B$2 -> 39600 | M11: =F11*Prices!C$2 -> 0 | N11: =G11*Prices!D$2 -> 0 | O11: =H11*Prices!E$2 -> 0 | P11: =I11*2000+J11*10000+K11*1800 -> 0 | Q11: =D11*Prices!A$2 -> 42572.25 | R11: =L11+M11+N11+O11 -> 39600 | S11: =R11+Q11+P11 -> 82172.25 | T11: 10 | U11: Available | V11: A
